Workbook

Sheet PBO_wage_only
B1: Wage_1ppt_lower | C1: Actual total baseline | E1: Change Gov Tax Rev | G1: Income tax revenue | I1: Individuals | J1: Companies | K1: Superannuation funds | L1: Other income tax
G3: Income tax revenue | I3: Individuals | J3: Companies | K3: Superannuation funds | L3: Other income tax | N3: Individual and other | O3: Companies | Q3: Individual and other | R3: Companies | S3: Total
B4: -1184.8123 | C4: 815327 | D4: 2027 | E4: =B4/C4 -> -0.0014531744 | F4: 2027 | G4: -1184.8123 | H4: 2027 | I4: -2314.1471 | J4: 1656.0517 | K4: -470.38842 | L4: -56.328502 | M4: 2027 | N4: =I4/1000+(K4+L4)/1000 -> -2.840864 | O4: =J4/1000 -> 1.6560517 | P4: 2027 | Q4: =N4/($C4/1000) -> -0.0034843247 | R4: =O4/($C4/1000) -> 0.0020311503 | S4: =E4 -> -0.0014531744
B5: -271.72591 | C5: 836286 | D5: 2028 | E5: =B5/C5 -> -0.00032491983 | F5: 2028 | G5: -268.41273 | H5: 2028 | I5: -4415.7928 | J5: 5133.5772 | K5: -869.66142 | L5: -116.53574 | M5: 2028 | N5: =I5/1000 -> -4.4157928 | O5: =J5/1000 -> 5.1335772 | P5: 2028 | Q5: =N5/($C5/1000) -> -0.0052802424 | R5: =O5/($C5/1000) -> 0.0061385426 | S5: =E5 -> -0.00032491983
B6: 574.36284 | C6: 863473 | D6: 2029 | E6: =B6/C6 -> 0.00066517754 | F6: 2029 | G6: 580.965 | H6: 2029 | I6: -6751.214 | J6: 8812.6794 | K6: -1297.928 | L6: -182.57242 | M6: 2029 | N6: =I6/1000 -> -6.751214 | O6: =J6/1000 -> 8.8126794 | P6: 2029 | Q6: =N6/($C6/1000) -> -0.0078186741 | R6: =O6/($C6/1000) -> 0.010206086 | S6: =E6 -> 0.00066517754
B7: 1205.3031 | C7: 910149 | D7: 2030 | E7: =B7/C7 -> 0.0013242921 | F7: 2030 | G7: 1215.4736 | H7: 2030 | I7: -9310.8221 | J7: 12593.075 | K7: -1808.6771 | L7: -258.10255 | M7: 2030 | N7: =I7/1000 -> -9.3108221 | O7: =J7/1000 -> 12.593075 | P7: 2030 | Q7: =N7/($C7/1000) -> -0.010229998 | R7: =O7/($C7/1000) -> 0.013836279 | S7: =E7 -> 0.0013242921
B8: 2061.705 | C8: 966032.36 | D8: 2031 | E8: =B8/C8 -> 0.0021341987 | F8: 2031 | G8: 2075.9634 | H8: 2031 | I8: -12530.462 | J8: 17275.396 | K8: -2333.7441 | L8: -335.22722 | M8: 2031 | N8: =I8/1000 -> -12.530462 | O8: =J8/1000 -> 17.275396 | P8: 2031 | Q8: =N8/($C8/1000) -> -0.012971058 | R8: =O8/($C8/1000) -> 0.017882834 | S8: =E8 -> 0.0021341987
B9: 2647.1753 | C9: 1021838.3 | D9: 2032 | E9: =B9/C9 -> 0.002590601 | F9: 2032 | G9: 2665.8072 | H9: 2032 | I9: -15845.639 | J9: 21985.827 | K9: -3053.8748 | L9: -420.50626 | M9: 2032 | N9: =I9/1000 -> -15.845639 | O9: =J9/1000 -> 21.985827 | P9: 2032 | Q9: =N9/($C9/1000) -> -0.015506993 | R9: =O9/($C9/1000) -> 0.021515956 | S9: =E9 -> 0.002590601
B10: 3246.274 | C10: 1080552.6 | D10: 2033 | E10: =B10/C10 -> 0.0030042721 | F10: 2033 | G10: 3269.5942 | H10: 2033 | I10: -19508.91 | J10: 27032.495 | K10: -3741.4448 | L10: -512.54544 | M10: 2033 | N10: =I10/1000 -> -19.50891 | O10: =J10/1000 -> 27.032495 | P10: 2033 | Q10: =N10/($C10/1000) -> -0.018054568 | R10: =O10/($C10/1000) -> 0.025017288 | S10: =E10 -> 0.0030042721
B11: 3802.6753 | C11: 1142744.7 | D11: 2034 | E11: =B11/C11 -> 0.0033276682 | F11: 2034 | G11: 3831.0388 | H11: 2034 | I11: -23520.789 | J11: 32449.059 | K11: -4485.5093 | L11: -611.72228 | M11: 2034 | N11: =I11/1000 -> -23.520789 | O11: =J11/1000 -> 32.449059 | P11: 2034 | Q11: =N11/($C11/1000) -> -0.020582715 | R11: =O11/($C11/1000) -> 0.02839572 | S11: =E11 -> 0.0033276682
B12: 4248.0743 | C12: 1208046.8 | D12: 2035 | E12: =B12/C12 -> 0.0035164816 | F12: 2035 | G12: 4281.8553 | H12: 2035 | I12: -27967.333 | J12: 38256.276 | K12: -5288.712 | L12: -718.37498 | M12: 2035 | N12: =I12/1000 -> -27.967333 | O12: =J12/1000 -> 38.256276 | P12: 2035 | Q12: =N12/($C12/1000) -> -0.023150869 | R12: =O12/($C12/1000) -> 0.031667876 | S12: =E12 -> 0.0035164816
B13: 4622.204 | C13: 1278062.3 | D13: 2036 | E13: =B13/C13 -> 0.0036165717 | F13: 2036 | G13: 4661.7941 | H13: 2036 | I13: -32826.679 | J13: 44475.544 | K13: -6154.1588 | L13: -832.91206 | M13: 2036 | N13: =I13/1000 -> -32.826679 | O13: =J13/1000 -> 44.475544 | P13: 2036 | Q13: =N13/($C13/1000) -> -0.025684724 | R13: =O13/($C13/1000) -> 0.034799197 | S13: =E13 -> 0.0036165717
B14: 4907.5979 | C14: 1350470.5 | D14: 2037 | E14: =B14/C14 -> 0.0036339912 | F14: 2037 | G14: 4953.4093 | H14: 2037 | I14: -38141.488 | J14: 51137.526 | K14: -7086.6376 | L14: -955.9911 | M14: 2037 | N14: =I14/1000 -> -38.141488 | O14: =J14/1000 -> 51.137526 | P14: 2037 | Q14: =N14/($C14/1000) -> -0.028243111 | R14: =O14/($C14/1000) -> 0.037866452 | S14: =E14 -> 0.0036339912
J40: Wage to much lower (1ppt decline)

Sheet PBO_prod_only
A1: Changes | B1: Tax rev | D1: Income tax | E1: Individual | F1: Corporate | H1: Actual total baseline | I1: Income tax | J1: Individual | K1: Corporate | M1: Prod to much higher (0.6ppt increase)
A2: 2026-27 | B2: 3062.5542 | D2: 2397.549 | E2: 976.05295 | F2: 1562.9912 | H2: 815327 | I2: =D2/$H2 -> 0.002940598 | J2: =E2/$H2 -> 0.0011971307 | K2: =F2/$H2 -> 0.0019170114
A3: 2027-28 | B3: 8488.0797 | D3: 7018.5244 | E3: 2360.8081 | F3: 4916.4756 | H3: 836286 | I3: =D3/$H3 -> 0.008392493 | J3: =E3/$H3 -> 0.0028229674 | K3: =F3/$H3 -> 0.0058789405
A4: 2028-29 | B4: 14436.552 | D4: 12056.612 | E4: 3935.0233 | F4: 8512.8524 | H4: 863473 | I4: =D4/$H4 -> 0.013962929 | J4: =E4/$H4 -> 0.0045572048 | K4: =F4/$H4 -> 0.0098588519
A5: 2029-30 | B5: 21015.549 | D5: 17636.969 | E5: 5910.6556 | F5: 12287.634 | H5: 910149 | I5: =D5/$H5 -> 0.019378112 | J5: =E5/$H5 -> 0.0064941626 | K5: =F5/$H5 -> 0.013500684
A6: 2030-31 | B6: 28633.174 | D6: 24153.189 | E6: 7853.1327 | F6: 17033.103 | H6: 966032.36 | I6: =D6/$H6 -> 0.025002463 | J6: =E6/$H6 -> 0.0081292646 | K6: =F6/$H6 -> 0.017632022
A7: 2031-32 | B7: 36812.076 | D7: 31144.691 | E7: 10223.859 | F7: 21900.275 | H7: 1021838.3 | I7: =D7/$H7 -> 0.03047908 | J7: =E7/$H7 -> 0.010005359 | K7: =F7/$H7 -> 0.021432231
A8: 2032-33 | B8: 45839.264 | D8: 38868.748 | E8: 12886.191 | F8: 27205.287 | H8: 1080552.6 | I8: =D8/$H8 -> 0.035971177 | J8: =E8/$H8 -> 0.011925557 | K8: =F8/$H8 -> 0.025177198
A9: 2033-34 | B9: 55797.388 | D9: 47406.39 | E9: 15905.206 | F9: 32993.929 | H9: 1142744.7 | I9: =D9/$H9 -> 0.041484672 | J9: =E9/$H9 -> 0.013918424 | K9: =F9/$H9 -> 0.028872528
A10: 2034-35 | B10: 66726.483 | D10: 56790.503 | E10: 19281.903 | F10: 39299.85 | H10: 1208046.8 | I10: =D10/$H10 -> 0.047010185 | J10: =E10/$H10 -> 0.015961222 | K10: =F10/$H10 -> 0.032531729
A11: 2035-36 | B11: 78768.348 | D11: 67138.867 | E11: 23100.834 | F11: 46158.252 | H11: 1278062.3 | I11: =D11/$H11 -> 0.052531762 | J11: =E11/$H11 -> 0.018074889 | K11: =F11/$H11 -> 0.036115807
A12: 2036-37 | B12: 91847.835 | D12: 78486.09 | E12: 27353.434 | F12: 53614.938 | H12: 1350470.5 | I12: =D12/$H12 -> 0.05811759 | J12: =E12/$H12 -> 0.020254744 | K12: =F12/$H12 -> 0.039700933
A14: Changes | B14: Tax rev | D14: Income tax | E14: Individual | F14: Corporate | H14: Actual total baseline | I14: Income tax | J14: Individual | K14: Corporate | M14: Prod to much higher (0.3ppt increase)
A15: 2026-27 | B15: 1530.7282 | D15: 1198.7836 | E15: 488.03555 | F15: 781.4956 | H15: 815327 | I15: =D15/$H15 -> 0.0014703102 | J15: =E15/$H15 -> 0.00059857647 | K15: =F15/$H15 -> 0.00095850573
A16: 2027-28 | B16: 4238.1962 | D16: 3505.5422 | E16: 1178.9235 | F16: 2455.7942 | H16: 836286 | I16: =D16/$H16 -> 0.0041917983 | J16: =E16/$H16 -> 0.0014097133 | K16: =F16/$H16 -> 0.0029365483
A17: 2028-29 | B17: 7198.3848 | D17: 6013.425 | E17: 1962.2438 | F17: 4246.2235 | H17: 863473 | I17: =D17/$H17 -> 0.0069642305 | J17: =E17/$H17 -> 0.0022725016 | K17: =F17/$H17 -> 0.00491761
A18: 2029-30 | B18: 10463.686 | D18: 8783.8242 | E18: 2943.1376 | F18: 6120.1147 | H18: 910149 | I18: =D18/$H18 -> 0.0096509739 | J18: =E18/$H18 -> 0.0032336877 | K18: =F18/$H18 -> 0.0067242997
A19: 2030-31 | B19: 14235.645 | D19: 12011.36 | E19: 3904.6602 | F19: 8471.1098 | H19: 966032.36 | I19: =D19/$H19 -> 0.012433703 | J19: =E19/$H19 -> 0.0040419559 | K19: =F19/$H19 -> 0.008768971
A20: 2031-32 | B20: 18274.917 | D20: 15465.187 | E20: 5075.9673 | F20: 10875.455 | H20: 1021838.3 | I20: =D20/$H20 -> 0.015134672 | J20: =E20/$H20 -> 0.0049674859 | K20: =F20/$H20 -> 0.010643029
A21: 2032-33 | B21: 22722.554 | D21: 19271.804 | E21: 6388.366 | F21: 13489.592 | H21: 1080552.6 | I21: =D21/$H21 -> 0.017835137 | J21: =E21/$H21 -> 0.0059121287 | K21: =F21/$H21 -> 0.012483975
A22: 2033-34 | B22: 27617.607 | D22: 23469.718 | E22: 7873.4724 | F22: 16335.21 | H22: 1142744.7 | I22: =D22/$H22 -> 0.020538024 | J22: =E22/$H22 -> 0.006889966 | K22: =F22/$H22 -> 0.014294715
A23: 2034-35 | B23: 32977.753 | D23: 28073.333 | E23: 9530.957 | F23: 19427.856 | H23: 1208046.8 | I23: =D23/$H23 -> 0.023238614 | J23: =E23/$H23 -> 0.0078895595 | K23: =F23/$H23 -> 0.01608204
A24: 2035-36 | B24: 38870.845 | D24: 33138.933 | E24: 11401.805 | F24: 22783.745 | H24: 1278062.3 | I24: =D24/$H24 -> 0.025929043 | J24: =E24/$H24 -> 0.0089211653 | K24: =F24/$H24 -> 0.017826787
A25: 2036-37 | B25: 45293.822 | D25: 38681.43 | E25: 13480.825 | F25: 26424.211 | H25: 1350470.5 | I25: =D25/$H25 -> 0.028642929 | J25: =E25/$H25 -> 0.0099823175 | K25: =F25/$H25 -> 0.019566671

Sheet PBO_prod_wage
A1: Changes | B1: Tax rev | D1: Income tax | E1: Individual | F1: Corporate | H1: Actual total baseline | I1: Income tax | J1: Individual | K1: Corporate | M1: Prod to much higher and wage to lower (0.6ppt and 0.5ppt respectively)
A2: 2026-27 | B2: 2470.139 | D2: 1805.1337 | E2: -181.02967 | F2: 2391.017 | H2: 815327 | I2: =D2/$H2 -> 0.0022139997 | J2: =E2/$H2 -> -0.00022203321 | K2: =F2/$H2 -> 0.0029325866
A3: 2027-28 | B3: 8349.2193 | D3: 6881.3206 | E3: 146.95551 | F3: 7487.4654 | H3: 836286 | I3: =D3/$H3 -> 0.0082284298 | J3: =E3/$H3 -> 0.00017572399 | K3: =F3/$H3 -> 0.0089532353
A4: 2028-29 | B4: 14719.922 | D4: 12343.291 | E4: 541.94477 | F4: 12936.491 | H4: 863473 | I4: =D4/$H4 -> 0.014294936 | J4: =E4/$H4 -> 0.00062763372 | K4: =F4/$H4 -> 0.014981929
A5: 2029-30 | B5: 21614.916 | D5: 18241.446 | E5: 1219.7425 | F5: 18623.901 | H5: 910149 | I5: =D5/$H5 -> 0.020042263 | J5: =E5/$H5 -> 0.0013401569 | K5: =F5/$H5 -> 0.020462475
A6: 2030-31 | B6: 29663.59 | D6: 25190.785 | E6: 1524.9083 | F6: 25746.177 | H6: 966032.36 | I6: =D6/$H6 -> 0.026076544 | J6: =E6/$H6 -> 0.0015785271 | K6: =F6/$H6 -> 0.026651464
A7: 2031-32 | B7: 38138.57 | D7: 32480.591 | E7: 2202.0165 | F7: 33015.848 | H7: 1021838.3 | I7: =D7/$H7 -> 0.03178643 | J7: =E7/$H7 -> 0.0021549559 | K7: =F7/$H7 -> 0.032310248
A8: 2032-33 | B8: 47470.011 | D8: 40511.297 | E8: 2985.9995 | F8: 40905.366 | H8: 1080552.6 | I8: =D8/$H8 -> 0.037491277 | J8: =E8/$H8 -> 0.0027634005 | K8: =F8/$H8 -> 0.03785597
A9: 2033-34 | B9: 57706.118 | D9: 49329.508 | E9: 3934.4414 | F9: 49478.857 | H9: 1142744.7 | I9: =D9/$H9 -> 0.043167566 | J9: =E9/$H9 -> 0.0034429749 | K9: =F9/$H9 -> 0.043298258
A10: 2034-35 | B10: 68836.282 | D10: 58917.478 | E10: 4987.5162 | F10: 58781.9 | H10: 1208046.8 | I10: =D10/$H10 -> 0.048770858 | J10: =E10/$H10 -> 0.0041285787 | K10: =F10/$H10 -> 0.048658629
A11: 2035-36 | B11: 81037.703 | D11: 69428.4 | E11: 6254.8578 | F11: 68862.06 | H11: 1278062.3 | I11: =D11/$H11 -> 0.054323172 | J11: =E11/$H11 -> 0.0048940162 | K11: =F11/$H11 -> 0.053880048
A12: 2036-37 | B12: 94226.331 | D12: 80887.99 | E12: 7704.84 | F12: 79782.346 | H12: 1350470.5 | I12: =D12/$H12 -> 0.059896155 | J12: =E12/$H12 -> 0.0057053006 | K12: =F12/$H12 -> 0.059077445
I14: Income tax | J14: Individual | K14: Corporate | M14: Fiddle in the Prod 0.3% case
I15: =PBO_wage_only!S4+PBO_prod_only!I15 -> 1.7135791e-05 | J15: =PBO_wage_only!Q4+PBO_prod_only!J15 -> -0.0028857482 | K15: =PBO_wage_only!R4+PBO_prod_only!K15 -> 0.0029896561
I16: =PBO_wage_only!S5+PBO_prod_only!I16 -> 0.0038668785 | J16: =PBO_wage_only!Q5+PBO_prod_only!J16 -> -0.0038705291 | K16: =PBO_wage_only!R5+PBO_prod_only!K16 -> 0.0090750908
I17: =PBO_wage_only!S6+PBO_prod_only!I17 -> 0.0076294081 | J17: =PBO_wage_only!Q6+PBO_prod_only!J17 -> -0.0055461725 | K17: =PBO_wage_only!R6+PBO_prod_only!K17 -> 0.015123696
I18: =PBO_wage_only!S7+PBO_prod_only!I18 -> 0.010975266 | J18: =PBO_wage_only!Q7+PBO_prod_only!J18 -> -0.0069963099 | K18: =PBO_wage_only!R7+PBO_prod_only!K18 -> 0.020560578
I19: =PBO_wage_only!S8+PBO_prod_only!I19 -> 0.014567902 | J19: =PBO_wage_only!Q8+PBO_prod_only!J19 -> -0.0089291018 | K19: =PBO_wage_only!R8+PBO_prod_only!K19 -> 0.026651805
I20: =PBO_wage_only!S9+PBO_prod_only!I20 -> 0.017725273 | J20: =PBO_wage_only!Q9+PBO_prod_only!J20 -> -0.010539507 | K20: =PBO_wage_only!R9+PBO_prod_only!K20 -> 0.032158985
I21: =PBO_wage_only!S10+PBO_prod_only!I21 -> 0.02083941 | J21: =PBO_wage_only!Q10+PBO_prod_only!J21 -> -0.01214244 | K21: =PBO_wage_only!R10+PBO_prod_only!K21 -> 0.037501263
I22: =PBO_wage_only!S11+PBO_prod_only!I22 -> 0.023865692 | J22: =PBO_wage_only!Q11+PBO_prod_only!J22 -> -0.013692749 | K22: =PBO_wage_only!R11+PBO_prod_only!K22 -> 0.042690435
I23: =PBO_wage_only!S12+PBO_prod_only!I23 -> 0.026755096 | J23: =PBO_wage_only!Q12+PBO_prod_only!J23 -> -0.01526131 | K23: =PBO_wage_only!R12+PBO_prod_only!K23 -> 0.047749916
I24: =PBO_wage_only!S13+PBO_prod_only!I24 -> 0.029545615 | J24: =PBO_wage_only!Q13+PBO_prod_only!J24 -> -0.016763559 | K24: =PBO_wage_only!R13+PBO_prod_only!K24 -> 0.052625985
I25: =PBO_wage_only!S14+PBO_prod_only!I25 -> 0.03227692 | J25: =PBO_wage_only!Q14+PBO_prod_only!J25 -> -0.018260794 | K25: =PBO_wage_only!R14+PBO_prod_only!K25 -> 0.057433123

Sheet R
A1: Year | B1: Shock | C1: Individual | D1: Corporate | E1: Total
A2: 2027 | B2: Wage | C2: =PBO_wage_only!Q4 -> -0.0034843247 | D2: =PBO_wage_only!R4 -> 0.0020311503 | E2: =PBO_wage_only!S4 -> -0.0014531744
A3: 2028 | B3: Wage | C3: =PBO_wage_only!Q5 -> -0.0052802424 | D3: =PBO_wage_only!R5 -> 0.0061385426 | E3: =PBO_wage_only!S5 -> -0.00032491983
A4: 2029 | B4: Wage | C4: =PBO_wage_only!Q6 -> -0.0078186741 | D4: =PBO_wage_only!R6 -> 0.010206086 | E4: =PBO_wage_only!S6 -> 0.00066517754
A5: 2030 | B5: Wage | C5: =PBO_wage_only!Q7 -> -0.010229998 | D5: =PBO_wage_only!R7 -> 0.013836279 | E5: =PBO_wage_only!S7 -> 0.0013242921
A6: 2031 | B6: Wage | C6: =PBO_wage_only!Q8 -> -0.012971058 | D6: =PBO_wage_only!R8 -> 0.017882834 | E6: =PBO_wage_only!S8 -> 0.0021341987
A7: 2032 | B7: Wage | C7: =PBO_wage_only!Q9 -> -0.015506993 | D7: =PBO_wage_only!R9 -> 0.021515956 | E7: =PBO_wage_only!S9 -> 0.002590601
A8: 2033 | B8: Wage | C8: =PBO_wage_only!Q10 -> -0.018054568 | D8: =PBO_wage_only!R10 -> 0.025017288 | E8: =PBO_wage_only!S10 -> 0.0030042721
A9: 2034 | B9: Wage | C9: =PBO_wage_only!Q11 -> -0.020582715 | D9: =PBO_wage_only!R11 -> 0.02839572 | E9: =PBO_wage_only!S11 -> 0.0033276682
A10: 2035 | B10: Wage | C10: =PBO_wage_only!Q12 -> -0.023150869 | D10: =PBO_wage_only!R12 -> 0.031667876 | E10: =PBO_wage_only!S12 -> 0.0035164816
A11: 2036 | B11: Wage | C11: =PBO_wage_only!Q13 -> -0.025684724 | D11: =PBO_wage_only!R13 -> 0.034799197 | E11: =PBO_wage_only!S13 -> 0.0036165717
A12: 2037 | B12: Wage | C12: =PBO_wage_only!Q14 -> -0.028243111 | D12: =PBO_wage_only!R14 -> 0.037866452 | E12: =PBO_wage_only!S14 -> 0.0036339912
A13: 2027 | B13: Prod | C13: =PBO_prod_only!J2 -> 0.0011971307 | D13: =PBO_prod_only!K2 -> 0.0019170114 | E13: =PBO_prod_only!I2 -> 0.002940598
A14: 2028 | B14: Prod | C14: =PBO_prod_only!J3 -> 0.0028229674 | D14: =PBO_prod_only!K3 -> 0.0058789405 | E14: =PBO_prod_only!I3 -> 0.008392493
A15: 2029 | B15: Prod | C15: =PBO_prod_only!J4 -> 0.0045572048 | D15: =PBO_prod_only!K4 -> 0.0098588519 | E15: =PBO_prod_only!I4 -> 0.013962929
A16: 2030 | B16: Prod | C16: =PBO_prod_only!J5 -> 0.0064941626 | D16: =PBO_prod_only!K5 -> 0.013500684 | E16: =PBO_prod_only!I5 -> 0.019378112
A17: 2031 | B17: Prod | C17: =PBO_prod_only!J6 -> 0.0081292646 | D17: =PBO_prod_only!K6 -> 0.017632022 | E17: =PBO_prod_only!I6 -> 0.025002463
A18: 2032 | B18: Prod | C18: =PBO_prod_only!J7 -> 0.010005359 | D18: =PBO_prod_only!K7 -> 0.021432231 | E18: =PBO_prod_only!I7 -> 0.03047908
A19: 2033 | B19: Prod | C19: =PBO_prod_only!J8 -> 0.011925557 | D19: =PBO_prod_only!K8 -> 0.025177198 | E19: =PBO_prod_only!I8 -> 0.035971177
A20: 2034 | B20: Prod | C20: =PBO_prod_only!J9 -> 0.013918424 | D20: =PBO_prod_only!K9 -> 0.028872528 | E20: =PBO_prod_only!I9 -> 0.041484672
A21: 2035 | B21: Prod | C21: =PBO_prod_only!J10 -> 0.015961222 | D21: =PBO_prod_only!K10 -> 0.032531729 | E21: =PBO_prod_only!I10 -> 0.047010185
A22: 2036 | B22: Prod | C22: =PBO_prod_only!J11 -> 0.018074889 | D22: =PBO_prod_only!K11 -> 0.036115807 | E22: =PBO_prod_only!I11 -> 0.052531762
A23: 2037 | B23: Prod | C23: =PBO_prod_only!J12 -> 0.020254744 | D23: =PBO_prod_only!K12 -> 0.039700933 | E23: =PBO_prod_only!I12 -> 0.05811759
A24: 2027 | B24: Prod_wage | C24: =PBO_prod_wage!J2 -> -0.00022203321 | D24: =PBO_prod_wage!K2 -> 0.0029325866 | E24: =PBO_prod_wage!I2 -> 0.0022139997
A25: 2028 | B25: Prod_wage | C25: =PBO_prod_wage!J3 -> 0.00017572399 | D25: =PBO_prod_wage!K3 -> 0.0089532353 | E25: =PBO_prod_wage!I3 -> 0.0082284298
A26: 2029 | B26: Prod_wage | C26: =PBO_prod_wage!J4 -> 0.00062763372 | D26: =PBO_prod_wage!K4 -> 0.014981929 | E26: =PBO_prod_wage!I4 -> 0.014294936
A27: 2030 | B27: Prod_wage | C27: =PBO_prod_wage!J5 -> 0.0013401569 | D27: =PBO_prod_wage!K5 -> 0.020462475 | E27: =PBO_prod_wage!I5 -> 0.020042263
A28: 2031 | B28: Prod_wage | C28: =PBO_prod_wage!J6 -> 0.0015785271 | D28: =PBO_prod_wage!K6 -> 0.026651464 | E28: =PBO_prod_wage!I6 -> 0.026076544
A29: 2032 | B29: Prod_wage | C29: =PBO_prod_wage!J7 -> 0.0021549559 | D29: =PBO_prod_wage!K7 -> 0.032310248 | E29: =PBO_prod_wage!I7 -> 0.03178643
A30: 2033 | B30: Prod_wage | C30: =PBO_prod_wage!J8 -> 0.0027634005 | D30: =PBO_prod_wage!K8 -> 0.03785597 | E30: =PBO_prod_wage!I8 -> 0.037491277
A31: 2034 | B31: Prod_wage | C31: =PBO_prod_wage!J9 -> 0.0034429749 | D31: =PBO_prod_wage!K9 -> 0.043298258 | E31: =PBO_prod_wage!I9 -> 0.043167566
A32: 2035 | B32: Prod_wage | C32: =PBO_prod_wage!J10 -> 0.0041285787 | D32: =PBO_prod_wage!K10 -> 0.048658629 | E32: =PBO_prod_wage!I10 -> 0.048770858
A33: 2036 | B33: Prod_wage | C33: =PBO_prod_wage!J11 -> 0.0048940162 | D33: =PBO_prod_wage!K11 -> 0.053880048 | E33: =PBO_prod_wage!I11 -> 0.054323172
A34: 2037 | B34: Prod_wage | C34: =PBO_prod_wage!J12 -> 0.0057053006 | D34: =PBO_prod_wage!K12 -> 0.059077445 | E34: =PBO_prod_wage!I12 -> 0.059896155
A35: 2028 | B35: Prod_2 | C35: =PBO_prod_only!J15 -> 0.00059857647 | D35: =PBO_prod_only!K15 -> 0.00095850573 | E35: =PBO_prod_only!I15 -> 0.0014703102
A36: 2029 | B36: Prod_2 | C36: =PBO_prod_only!J16 -> 0.0014097133 | D36: =PBO_prod_only!K16 -> 0.0029365483 | E36: =PBO_prod_only!I16 -> 0.0041917983
A37: 2030 | B37: Prod_2 | C37: =PBO_prod_only!J17 -> 0.0022725016 | D37: =PBO_prod_only!K17 -> 0.00491761 | E37: =PBO_prod_only!I17 -> 0.0069642305
A38: 2031 | B38: Prod_2 | C38: =PBO_prod_only!J18 -> 0.0032336877 | D38: =PBO_prod_only!K18 -> 0.0067242997 | E38: =PBO_prod_only!I18 -> 0.0096509739
A39: 2032 | B39: Prod_2 | C39: =PBO_prod_only!J19 -> 0.0040419559 | D39: =PBO_prod_only!K19 -> 0.008768971 | E39: =PBO_prod_only!I19 -> 0.012433703
A40: 2033 | B40: Prod_2 | C40: =PBO_prod_only!J20 -> 0.0049674859 | D40: =PBO_prod_only!K20 -> 0.010643029 | E40: =PBO_prod_only!I20 -> 0.015134672
...
