Workbook

Sheet Display
A1: Key fiscal variable selected from drop-down list box ↓ | B1: 3 | C1: =OFFSET($A$1,$B$1,1) -> 78
A2: Total Crown OBEGAL | B2: 41
A3: Total Crown OBEGAL excluding ACC | B3: 45
A4: Net core Crown debt excl. NZSF & advances (excludes Crown entity debt) | B4: 78
A5: Core Crown residual cash | B5: 51
A6: Core Crown revenue | B6: 47
A7: Core Crown expenses | B7: 48
A8: Core Crown operating balance | B8: 49
A9: Core Crown primary balance | B9: 50
A10: Total Crown revenue | B10: 34
A11: Total Crown expenses | B11: 35
A12: Total Crown operating balance (excluding minority interests) | B12: 39
A13: Core Crown tax revenue | B13: 140
... A20: Core Crown borrowings | B20: 71

Sheet Guide
A1: Explanation of the worksheets in the 2025 Long-Term Fiscal Model (LTFM) and how they link to one another
A3: Name of worksheet | D3: Purpose | I3: Provides inputs to these worksheets | N3: Uses outputs from these worksheets
A5: Display | D5: This is a hidden worksheet. It provides | I5: Each of the main modelling worksheets. | N5: None.
D6: offsets to allow the chosen fiscal variable | I6: This model only contains one, which
D7: track to be displayed at the top of each | I7: is labelled Long-Term Fiscal Model.
D8: of the main modelling worksheets. | I8: Other worksheets can be copied from this
I9: and run off a different set of parameters
I10: from the Assumptions worksheet.
A12: Guide | D12: This is this worksheet. It provides some | I12: None. Purely for information purposes | N12: None.
D13: information to help users know how the | I13: and to help users of the model.
D14: various worksheets in the model interact.
A16: Sources | D16: This is also an information worksheet. | I16: None. Purely for information purposes | N16: None.
D17: It provides lists of data and exogenous | I17: and to help users of the model.
D18: tracks used in the model. Information is
D19: provided about the data, distribution or
D20: track, including from where it is sourced
D21: and when it was produced.
A23: Statistics NZ | D23: These are the most recent New Zealand | I23: Used extensively throughout the | N23: None.
D24: (NZ) resident population projections and | I24: Population Treasury and Labour Force
D25: Labour Force projections, by gender and | I25: Treasury worksheets in calculations to
D26: single year of age. They are produced by | I26: produce the Population and Labour Force
D27: Statistics New Zealand and are updated | I27: age and gender distributions that match
D28: when a new version becomes available. | I28: the aggregate values in forecast years.
D29: As well as population and labour force
D30: numbers the worksheet has participation
D31: rates (numbers in labour force divided by
D32: numbers in demographic group).
A34: Population Treasury | D34: These are age and gender distributions | I34: Used in numerous places in the main | N34: Statistics NZ
D35: of the NZ population that match the | I35: modelling worksheets, wherever | N35: Economic Forecasts
D36: aggregate forecasts in forecast years and | I36: demographic growth is required. Used
D37: are projected out into post-forecast years. | I37: in projecting some economic variables.
D38: They also adjust population projections | I38: Used as a driver of recipient numbers for
D39: for alternative net migration totals to the | I39: some expense types, especially New
D40: values used in Statistics NZ projections. | I40: Zealand Superannuation (NZS) and other
I41: welfare expenses. Used in projecting age
I42: and gender group Labour Force numbers
I43: in the Labour Force Treasury worksheet.
A45: Labour Force Treasury | D45: These are age and gender distributions | I45: Used in the economic projections of the | N45: Statistics NZ
D46: of the NZ labour force that match the | I46: main modelling worksheets to project the | N46: Population Treasury
D47: aggregate forecasts in forecast years and | I47: aggregate labour force. This variable is | N47: Economic Forecasts
...

Sheet Sources
A1: LONG-TERM FISCAL MODEL (LTFM) - 2025 VERSION
A2: Unless otherwise stated, forecasts and projections are produced by the New Zealand Treasury
A3: Unless otherwise stated, all post-forecast projections are produced by the LTFM model
A4: The adjective "outturn", normally used before the word data, means it comes from a completed time period
A6: This version of the LTFM uses: | E6: Budget Economic and Fiscal Update (BEFU) 2025 data and forecasts
A8: Economic Data | C8: History | E8: Outturn data from Treasury databases | J8: Mainly Statistics New Zealand (Stats NZ) measures
C9: Forecasts | J9: BEFU 2025 version
A11: Fiscal Data | C11: History | E11: Outturn data from Treasury publications | J11: Mainly from Financial Statements published in past Budget EFU reports
C12: Forecasts | J12: BEFU 2025 version
A14: Demographic Data | C14: History | E14: Outturn data from Stats NZ | J14: Accessible from Stats NZ website
A15: (by gender and | C15: Forecasts | E15: Treasury forecasts aggregate population | J15: BEFU 2025 version
A16: single year of age) | C16: Projections | E16: Based on those of Stats NZ | J16: Uses National Population Projections, produced in 2025
A18: Labour Force | C18: History | E18: Outturn data from Stats NZ | J18: Based on Household Labour Force Survey (HLFS)
A19: (by gender and | C19: Forecasts | E19: Treasury forecasts aggregate labour force | J19: BEFU 2025 version
A20: single year of age) | C20: Projections | E20: Based on those of Stats NZ | J20: Uses National Labour Force Projections, produced in 2025
A22: Social welfare | C22: History | E22: Outturn data from Treasury publications | J22: Mainly from Financial Statements published in past Budget EFU reports
A23: transfers | C23: Forecasts | E23: Forecasts from Ministry of Social | J23: BEFU 2025 version
E24: Development (MSD) and Inland Revenue
E25: Department (IRD) for Working for Families
A27: New Zealand | C27: History | E27: Outturn data from Treasury publications | J27: Mainly from Financial Statements published in past Budget EFU reports
A28: Superannuation | C28: Forecasts | E28: Forecasts from the NZSF | J28: BEFU 2025 version
A29: Fund (NZSF) | C29: Projections | E29: Projection produced by Treasury | J29: 2025 update
A31: Accident Compen- | C31: History | E31: Outturn data from Treasury publications | J31: Mainly from Financial Statements published in past Budget EFU reports
A32: sation Corporation | C32: Forecasts | E32: Forecasts from ACC | J32: BEFU 2025 version
A33: (ACC) data | C33: Projections | E33: Projection produced by ACC | J33: Asset/liability track, 2025 update
A35: Student Loans | C35: History | E35: Outturn data from Treasury publications | J35: Mainly from Financial Statements published in past Budget EFU reports
A36: track | C36: Forecasts | E36: Forecasts from IRD and the | J36: BEFU 2025 version
E37: Ministry of Education (MoE)
C38: Projections | E38: Projection produced by the MoE | J38: 2025 updated track provided by the Ministry of Education
A40: KiwiSaver expenses | C40: History | E40: Outturn data from Treasury publications | J40: Mainly from Financial Statements published in past Budget EFU reports
A41: Inland Revenue | C41: Forecasts | E41: Forecasts from IRD | J41: BEFU 2025 version
A42: Department (IRD) | C42: Projections | E42: Projection from IRD | J42: BEFU 2025 version
A44: Government | C44: History | E44: Outturn data from Treasury publications | J44: Mainly from Financial Statements published in past Budget EFU reports
A45: Superannuation | C45: Forecasts | E45: Forecasts based on actuarial valuations | J45: BEFU 2025 version
A46: Fund (GSF) | C46: Projections | E46: Projection produced by actuaries for GSF | J46: 2012 version
A48: Tax Receivable write- | C48: History | E48: Outturn data from Treasury publications | J48: Mainly from Financial Statements published in past Budget EFU reports
A49: downs & impairments | C49: Forecasts | E49: Forecasts from IRD | J49: BEFU 2025 version
A51: Main benefit age & | E51: Based on administrative data from MSD | J51: 2025 update
A52: gender distribution
A54: Education age & | E54: Based on data from Minstry of Education | J54: 2025 update
...

Sheet Statistics NZ
A1: STATISTICS NEW ZEALAND OUTTURNS AND PROJECTIONS OF RESIDENT POPULATION OF NEW ZEALAND AND LABOUR FORCE, BY SINGLE YEAR OF AGE AND GENDER, AS AT 30 JUNE
A2: Population projections | B2: National population projections: 2024 (base) - 2078 50th percentile projection
A3: Labour Force projections | B3: National labour force projections: 2024 (base) - 2078 50th percentile projection
A4: Year ended 30 June | B4: 2005/06 | C4: 2006/07 | D4: 2007/08 | E4: 2008/09 | F4: 2009/10 | G4: 2010/11 | H4: 2011/12 | I4: 2012/13 | J4: 2013/14 | K4: 2014/15 | L4: 2015/16 | M4: 2016/17 | N4: 2017/18 | O4: 2018/19 | P4: 2019/20 | Q4: 2020/21 | R4: 2021/22 | S4: 2022/23 | T4: 2023/24 | U4: 2024/25 | V4: 2025/26 | W4: 2026/27 | X4: 2027/28 | Y4: 2028/29 | Z4: 2029/30 | AA4: 2030/31 | AB4: 2031/32 | AC4: 2032/33 | AD4: 2033/34 | AE4: 2034/35 | AF4: 2035/36 | AG4: 2036/37 | AH4: 2037/38 | AI4: 2038/39 | AJ4: 2039/40 | AK4: 2040/41 | AL4: 2041/42 | AM4: 2042/43 | AN4: 2043/44 | AO4: 2044/45 | AP4: 2045/46 | AQ4: 2046/47 | AR4: 2047/48 | AS4: 2048/49 | AT4: 2049/50 | AU4: 2050/51 | AV4: 2051/52 | AW4: 2052/53 | AX4: 2053/54 | AY4: 2054/55 | AZ4: 2055/56 | BA4: 2056/57 | BB4: 2057/58 | BC4: 2058/59 | BD4: 2059/60 | BE4: 2060/61 | BF4: 2061/62 | BG4: 2062/63 | BH4: 2063/64 | BI4: 2064/65
B5: 2006 | C5: 2007 | D5: 2008 | E5: 2009 | F5: 2010 | G5: 2011 | H5: 2012 | I5: 2013 | J5: 2014 | K5: 2015 | L5: 2016 | M5: 2017 | N5: 2018 | O5: 2019 | P5: 2020 | Q5: 2021 | R5: 2022 | S5: 2023 | T5: 2024 | U5: 2025 | V5: 2026 | W5: 2027 | X5: 2028 | Y5: 2029 | Z5: 2030 | AA5: 2031 | AB5: 2032 | AC5: 2033 | AD5: 2034 | AE5: 2035 | AF5: 2036 | AG5: 2037 | AH5: 2038 | AI5: 2039 | AJ5: 2040 | AK5: 2041 | AL5: 2042 | AM5: 2043 | AN5: 2044 | AO5: 2045 | AP5: 2046 | AQ5: 2047 | AR5: 2048 | AS5: 2049 | AT5: 2050 | AU5: 2051 | AV5: 2052 | AW5: 2053 | AX5: 2054 | AY5: 2055 | AZ5: 2056 | BA5: 2057 | BB5: 2058 | BC5: 2059 | BD5: 2060 | BE5: 2061 | BF5: 2062 | BG5: 2063 | BH5: 2064 | BI5: 2065
A6: Population (millions) | B6: =SUM(B$15:B$110,B$115:B$210)/1000000 -> 4.18463 | C6: =SUM(C$15:C$110,C$115:C$210)/1000000 -> 4.22386 | D6: =SUM(D$15:D$110,D$115:D$210)/1000000 -> 4.25975 | E6: =SUM(E$15:E$110,E$115:E$210)/1000000 -> 4.3026 | F6: =SUM(F$15:F$110,F$115:F$210)/1000000 -> 4.35065 | G6: =SUM(G$15:G$110,G$115:G$210)/1000000 -> 4.38397 | H6: =SUM(H$15:H$110,H$115:H$210)/1000000 -> 4.40798 | I6: =SUM(I$15:I$110,I$115:I$210)/1000000 -> 4.4421 | ... BI6: =SUM(BI$15:BI$110,BI$115:BI$210)/1000000 -> 7.28726
A7: Annual growth (%) | C7: =C$6/B$6-1 -> 0.0093747834 | D7: =D$6/C$6-1 -> 0.0084969672 | E7: =E$6/D$6-1 -> 0.010059276 | F7: =F$6/E$6-1 -> 0.011167666 | G7: =G$6/F$6-1 -> 0.0076586257 | H7: =H$6/G$6-1 -> 0.0054767711 | I7: =I$6/H$6-1 -> 0.007740507 | J7: =J$6/I$6-1 -> 0.016737579 | ... BI7: =BI$6/BH$6-1 -> 0.0059926696
A8: Working-age popn (15+, millions) | B8: =SUM(B$30:B$110,B$130:B$210)/1000000 -> 3.29632 | C8: =SUM(C$30:C$110,C$130:C$210)/1000000 -> 3.33256 | D8: =SUM(D$30:D$110,D$130:D$210)/1000000 -> 3.36424 | E8: =SUM(E$30:E$110,E$130:E$210)/1000000 -> 3.40144 | F8: =SUM(F$30:F$110,F$130:F$210)/1000000 -> 3.44251 | G8: =SUM(G$30:G$110,G$130:G$210)/1000000 -> 3.47326 | H8: =SUM(H$30:H$110,H$130:H$210)/1000000 -> 3.49817 | I8: =SUM(I$30:I$110,I$130:I$210)/1000000 -> 3.53331 | ... BI8: =SUM(BI$30:BI$110,BI$130:BI$210)/1000000 -> 6.2968
A9: =$A$7 -> Annual growth (%) | C9: =C$8/B$8-1 -> 0.010994078 | D9: =D$8/C$8-1 -> 0.0095062054 | E9: =E$8/D$8-1 -> 0.011057475 | F9: =F$8/E$8-1 -> 0.012074298 | G9: =G$8/F$8-1 -> 0.0089324359 | H9: =H$8/G$8-1 -> 0.0071719365 | I9: =I$8/H$8-1 -> 0.010045252 | J9: =J$8/I$8-1 -> 0.020216171 | ... BI9: =BI$8/BH$8-1 -> 0.0068677695
A10: Labour Force (LF, millions) | T10: =SUM(T$215:T$280,T$285:T$350)/1000000 -> 3.0711 | U10: =SUM(U$215:U$280,U$285:U$350)/1000000 -> 3.1062 | V10: =SUM(V$215:V$280,V$285:V$350)/1000000 -> 3.1441 | W10: =SUM(W$215:W$280,W$285:W$350)/1000000 -> 3.18293 | X10: =SUM(X$215:X$280,X$285:X$350)/1000000 -> 3.22259 | Y10: =SUM(Y$215:Y$280,Y$285:Y$350)/1000000 -> 3.2622 | Z10: =SUM(Z$215:Z$280,Z$285:Z$350)/1000000 -> 3.3017 | AA10: =SUM(AA$215:AA$280,AA$285:AA$350)/1000000 -> 3.34058 | ... BI10: =SUM(BI$215:BI$280,BI$285:BI$350)/1000000 -> 4.23825
A11: =$A$7 -> Annual growth (%) | U11: =U$10/T$10-1 -> 0.01142913 | V11: =V$10/U$10-1 -> 0.012201404 | W11: =W$10/V$10-1 -> 0.012350116 | X11: =X$10/W$10-1 -> 0.012460217 | Y11: =Y$10/X$10-1 -> 0.012291356 | Z11: =Z$10/Y$10-1 -> 0.012108393 | AA11: =AA$10/Z$10-1 -> 0.011775752 | AB11: =AB$10/AA$10-1 -> 0.011498003 | ... BI11: =BI$10/BH$10-1 -> 0.0042389749
A12: Total LF participation rate (%) | T12: =T$10/T$8 -> 0.7120153 | U12: =U$10/U$8 -> 0.71113451 | V12: =V$10/V$8 -> 0.71040264 | W12: =W$10/W$8 -> 0.70969447 | X12: =X$10/X$8 -> 0.70905474 | Y12: =Y$10/Y$8 -> 0.70853161 | Z12: =Z$10/Z$8 -> 0.70796479 | AA12: =AA$10/AA$8 -> 0.70744873 | ... BI12: =BI$10/BI$8 -> 0.67307998
A13: Age in years ↓
A14: FEMALE POPULATION
A15: 0 | B15: 28910 | C15: 30230 | D15: 31360 | E15: 30830 | F15: 31510 | G15: 30670 | H15: 29880 | I15: 29370 | J15: 28390 | K15: 28520 | L15: 28790 | M15: 29450 | N15: 29000 | O15: 28900 | P15: 29060 | Q15: 29540 | R15: 29820 | S15: 27560 | T15: 27820 | U15: 28280 | V15: 28290 | W15: 28280 | X15: 28270 | Y15: 28250 | Z15: 28240 | AA15: 28250 | AB15: 28270 | AC15: 28320 | AD15: 28400 | AE15: 28520 | AF15: 28680 | AG15: 28860 | AH15: 29070 | AI15: 29290 | AJ15: 29510 | AK15: 29730 | AL15: 29920 | AM15: 30080 | AN15: 30210 | AO15: 30300 | AP15: 30360 | AQ15: 30390 | AR15: 30390 | AS15: 30370 | AT15: 30330 | AU15: 30270 | AV15: 30200 | AW15: 30140 | AX15: 30080 | AY15: 30020 | AZ15: 29980 | BA15: 29950 | BB15: 29930 | BC15: 29940 | BD15: 29970 | BE15: 30020 | BF15: 30080 | BG15: 30160 | BH15: 30250 | BI15: 30360
A16: 1 | B16: 27990 | C16: 28850 | D16: 30110 | E16: 31260 | F16: 30820 | G16: 31460 | H16: 30640 | I16: 29950 | J16: 29510 | K16: 28670 | L16: 28900 | M16: 29040 | N16: 29620 | O16: 29110 | P16: 29080 | Q16: 29150 | R16: 29470 | S16: 30040 | T16: 27710 | U16: 27790 | V16: 28280 | W16: 28300 | X16: 28310 | Y16: 28300 | Z16: 28290 | AA16: 28290 | AB16: 28290 | AC16: 28320 | AD16: 28370 | AE16: 28450 | AF16: 28570 | AG16: 28730 | AH16: 28920 | AI16: 29130 | AJ16: 29350 | AK16: 29580 | AL16: 29790 | AM16: 29980 | AN16: 30140 | AO16: 30280 | AP16: 30370 | AQ16: 30430 | AR16: 30460 | AS16: 30460 | AT16: 30440 | AU16: 30400 | AV16: 30350 | AW16: 30290 | AX16: 30220 | AY16: 30160 | AZ16: 30110 | BA16: 30070 | BB16: 30040 | BC16: 30030 | BD16: 30030 | BE16: 30060 | BF16: 30110 | BG16: 30180 | BH16: 30260 | BI16: 30350
A17: 2 | B17: 28180 | C17: 28100 | D17: 28870 | E17: 30220 | F17: 31340 | G17: 30770 | H17: 31310 | I17: 30580 | J17: 30150 | K17: 29890 | L17: 29060 | M17: 29470 | N17: 29470 | O17: 29980 | P17: 29540 | Q17: 29260 | R17: 29240 | S17: 29840 | T17: 30450 | U17: 27780 | V17: 27890 | W17: 28390 | X17: 28430 | Y17: 28440 | Z17: 28440 | AA17: 28440 | AB17: 28430 | AC17: 28440 | AD17: 28470 | AE17: 28520 | AF17: 28610 | AG17: 28730 | AH17: 28890 | AI17: 29070 | AJ17: 29280 | AK17: 29510 | AL17: 29740 | AM17: 29950 | AN17: 30150 | AO17: 30310 | AP17: 30440 | AQ17: 30540 | AR17: 30600 | AS17: 30640 | AT17: 30640 | AU17: 30620 | AV17: 30580 | AW17: 30530 | AX17: 30470 | AY17: 30410 | AZ17: 30350 | BA17: 30300 | BB17: 30250 | BC17: 30230 | BD17: 30220 | BE17: 30230 | BF17: 30260 | BG17: 30310 | BH17: 30380 | BI17: 30460
A18: 3 | B18: 27310 | C18: 28260 | D18: 28090 | E18: 28910 | F18: 30280 | G18: 31290 | H18: 30670 | I18: 31320 | J18: 30730 | K18: 30430 | L18: 30460 | M18: 29610 | N18: 30030 | O18: 29920 | P18: 30490 | Q18: 29680 | R18: 29450 | S18: 29740 | T18: 30340 | U18: 30570 | V18: 27930 | W18: 28060 | X18: 28580 | Y18: 28620 | Z18: 28640 | AA18: 28650 | AB18: 28640 | AC18: 28640 | AD18: 28650 | AE18: 28680 | AF18: 28730 | AG18: 28820 | AH18: 28950 | AI18: 29110 | AJ18: 29300 | AK18: 29510 | AL18: 29730 | AM18: 29960 | AN18: 30180 | AO18: 30380 | AP18: 30540 | AQ18: 30680 | AR18: 30780 | AS18: 30840 | AT18: 30880 | AU18: 30880 | AV18: 30860 | AW18: 30830 | AX18: 30780 | AY18: 30720 | AZ18: 30660 | BA18: 30600 | BB18: 30550 | BC18: 30510 | BD18: 30480 | BE18: 30480 | BF18: 30490 | BG18: 30520 | BH18: 30570 | BI18: 30640
A19: 4 | B19: 27400 | C19: 27460 | D19: 28310 | E19: 28190 | F19: 29030 | G19: 30250 | H19: 31140 | I19: 30550 | J19: 31460 | K19: 31040 | L19: 30880 | M19: 30980 | N19: 30100 | O19: 30500 | P19: 30420 | Q19: 30610 | R19: 29800 | S19: 30210 | T19: 30430 | U19: 30500 | V19: 30770 | W19: 28150 | X19: 28290 | Y19: 28820 | Z19: 28870 | AA19: 28900 | AB19: 28910 | AC19: 28900 | AD19: 28900 | AE19: 28910 | AF19: 28940 | AG19: 29000 | AH19: 29090 | AI19: 29220 | AJ19: 29380 | AK19: 29570 | AL19: 29780 | AM19: 30010 | AN19: 30240 | AO19: 30460 | AP19: 30660 | AQ19: 30830 | AR19: 30970 | AS19: 31070 | AT19: 31130 | AU19: 31170 | AV19: 31180 | AW19: 31160 | AX19: 31130 | AY19: 31080 | AZ19: 31020 | BA19: 30960 | BB19: 30910 | BC19: 30860 | BD19: 30820 | BE19: 30800 | BF19: 30790 | BG19: 30810 | BH19: 30840 | BI19: 30890
A20: 5 | B20: 28370 | C20: 27650 | D20: 27610 | E20: 28410 | F20: 28320 | G20: 29050 | H20: 30120 | I20: 31090 | J20: 30700 | K20: 31720 | L20: 31400 | M20: 31390 | N20: 31470 | O20: 30590 | P20: 30990 | Q20: 30490 | R20: 30660 | S20: 30490 | T20: 31010 | U20: 30610 | V20: 30720 | W20: 31000 | X20: 28400 | Y20: 28560 | Z20: 29090 | AA20: 29150 | AB20: 29180 | AC20: 29180 | AD20: 29180 | AE20: 29180 | AF20: 29200 | AG20: 29230 | AH20: 29290 | AI20: 29380 | AJ20: 29510 | AK20: 29670 | AL20: 29870 | AM20: 30080 | AN20: 30310 | AO20: 30550 | AP20: 30770 | AQ20: 30970 | AR20: 31140 | AS20: 31280 | AT20: 31380 | AU20: 31450 | AV20: 31490 | AW20: 31490 | AX20: 31480 | AY20: 31450 | AZ20: 31400 | BA20: 31350 | BB20: 31290 | BC20: 31240 | BD20: 31190 | BE20: 31150 | BF20: 31130 | BG20: 31130 | BH20: 31140 | BI20: 31180
A21: 6 | B21: 28910 | C21: 28620 | D21: 27860 | E21: 27770 | F21: 28550 | G21: 28290 | H21: 28900 | I21: 30050 | J21: 31180 | K21: 30870 | L21: 31990 | M21: 31750 | N21: 31830 | O21: 31890 | P21: 31080 | Q21: 31090 | R21: 30550 | S21: 31420 | T21: 31240 | U21: 31200 | V21: 30840 | W21: 30970 | X21: 31270 | Y21: 28680 | Z21: 28840 | AA21: 29380 | AB21: 29440 | AC21: 29470 | AD21: 29480 | AE21: 29480 | AF21: 29490 | AG21: 29500 | AH21: 29530 | AI21: 29600 | AJ21: 29690 | AK21: 29820 | AL21: 29990 | AM21: 30180 | AN21: 30400 | AO21: 30630 | AP21: 30870 | AQ21: 31090 | AR21: 31290 | AS21: 31470 | AT21: 31610 | AU21: 31710 | AV21: 31780 | AW21: 31820 | AX21: 31830 | AY21: 31820 | AZ21: 31790 | BA21: 31750 | BB21: 31690 | BC21: 31640 | BD21: 31590 | BE21: 31540 | BF21: 31510 | BG21: 31490 | BH21: 31490 | BI21: 31510
A22: 7 | B22: 27980 | C22: 29160 | D22: 28760 | E22: 27990 | F22: 27850 | G22: 28600 | H22: 28200 | I22: 28790 | J22: 30150 | K22: 31310 | L22: 31080 | M22: 32270 | N22: 32050 | O22: 32190 | P22: 32370 | Q22: 31220 | R22: 31170 | S22: 31190 | T22: 32120 | U22: 31440 | V22: 31440 | W22: 31100 | X22: 31250 | Y22: 31560 | Z22: 28980 | AA22: 29140 | AB22: 29690 | AC22: 29750 | AD22: 29780 | AE22: 29790 | AF22: 29790 | AG22: 29800 | AH22: 29820 | AI22: 29850 | AJ22: 29920 | AK22: 30010 | AL22: 30150 | AM22: 30310 | AN22: 30510 | AO22: 30730 | AP22: 30970 | AQ22: 31200 | AR22: 31430 | AS22: 31630 | AT22: 31810 | AU22: 31950 | AV22: 32060 | AW22: 32130 | AX22: 32170 | AY22: 32180 | AZ22: 32170 | BA22: 32150 | BB22: 32100 | BC22: 32050 | BD22: 32000 | BE22: 31950 | BF22: 31910 | BG22: 31880 | BH22: 31860 | BI22: 31860
A23: 8 | B23: 28620 | C23: 28230 | D23: 29340 | E23: 28950 | F23: 28120 | G23: 27910 | H23: 28490 | I23: 28140 | J23: 28910 | K23: 30320 | L23: 31560 | M23: 31380 | N23: 32500 | O23: 32460 | P23: 32650 | Q23: 32520 | R23: 31310 | S23: 31870 | T23: 31910 | U23: 32320 | V23: 31680 | W23: 31700 | X23: 31380 | Y23: 31540 | Z23: 31860 | AA23: 29280 | AB23: 29450 | AC23: 29990 | AD23: 30050 | AE23: 30090 | AF23: 30100 | AG23: 30110 | AH23: 30110 | AI23: 30130 | AJ23: 30170 | AK23: 30240 | AL23: 30330 | AM23: 30470 | AN23: 30640 | AO23: 30840 | AP23: 31060 | AQ23: 31300 | AR23: 31540 | AS23: 31770 | AT23: 31970 | AU23: 32150 | AV23: 32290 | AW23: 32400 | AX23: 32480 | AY23: 32520 | AZ23: 32540 | BA23: 32530 | BB23: 32500 | BC23: 32460 | BD23: 32410 | BE23: 32360 | BF23: 32310 | BG23: 32270 | BH23: 32240 | BI23: 32230
A24: 9 | B24: 28770 | C24: 28910 | D24: 28390 | E24: 29550 | F24: 29150 | G24: 28210 | H24: 27850 | I24: 28430 | J24: 28290 | K24: 29120 | L24: 30590 | M24: 31900 | N24: 31640 | O24: 32820 | P24: 32920 | Q24: 32770 | R24: 32570 | S24: 32040 | T24: 32620 | U24: 32110 | V24: 32570 | W24: 31940 | X24: 31980 | Y24: 31660 | Z24: 31830 | AA24: 32160 | AB24: 29580 | AC24: 29750 | AD24: 30300 | AE24: 30360 | AF24: 30400 | AG24: 30410 | AH24: 30420 | AI24: 30430 | AJ24: 30450 | AK24: 30490 | AL24: 30560 | AM24: 30660 | AN24: 30800 | AO24: 30970 | AP24: 31170 | AQ24: 31390 | AR24: 31630 | AS24: 31870 | AT24: 32100 | AU24: 32310 | AV24: 32490 | AW24: 32640 | AX24: 32750 | AY24: 32820 | AZ24: 32870 | BA24: 32890 | BB24: 32880 | BC24: 32860 | BD24: 32820 | BE24: 32770 | BF24: 32720 | BG24: 32680 | BH24: 32640 | BI24: 32610
A25: 10 | B25: 29250 | C25: 28990 | D25: 29090 | E25: 28550 | F25: 29770 | G25: 29310 | H25: 28210 | I25: 27900 | J25: 28540 | K25: 28530 | L25: 29430 | M25: 30950 | N25: 32130 | O25: 31950 | P25: 33220 | Q25: 33040 | R25: 32810 | S25: 33270 | T25: 32820 | U25: 32830 | V25: 32370 | W25: 32840 | X25: 32230 | Y25: 32280 | Z25: 31970 | AA25: 32140 | AB25: 32470 | AC25: 29900 | AD25: 30070 | AE25: 30620 | AF25: 30680 | AG25: 30720 | AH25: 30740 | AI25: 30750 | AJ25: 30760 | AK25: 30780 | AL25: 30820 | AM25: 30890 | AN25: 31000 | AO25: 31130 | AP25: 31310 | AQ25: 31510 | AR25: 31740 | AS25: 31980 | AT25: 32220 | AU25: 32450 | AV25: 32660 | AW25: 32840 | AX25: 32990 | AY25: 33100 | AZ25: 33180 | BA25: 33230 | BB25: 33250 | BC25: 33250 | BD25: 33220 | BE25: 33190 | BF25: 33140 | BG25: 33100 | BH25: 33050 | BI25: 33010
A26: 11 | B26: 29970 | C26: 29430 | D26: 29180 | E26: 29270 | F26: 28700 | G26: 29880 | H26: 29380 | I26: 28280 | J26: 28040 | K26: 28740 | L26: 28830 | M26: 29750 | N26: 31280 | O26: 32550 | P26: 32410 | Q26: 33350 | R26: 33060 | S26: 33500 | T26: 33950 | U26: 33030 | V26: 33080 | W26: 32640 | X26: 33120 | Y26: 32530 | Z26: 32580 | AA26: 32280 | AB26: 32460 | AC26: 32780 | AD26: 30210 | AE26: 30390 | AF26: 30940 | AG26: 31000 | AH26: 31040 | AI26: 31060 | AJ26: 31080 | AK26: 31090 | AL26: 31110 | AM26: 31160 | AN26: 31230 | AO26: 31330 | AP26: 31470 | AQ26: 31650 | AR26: 31860 | AS26: 32080 | AT26: 32330 | AU26: 32570 | AV26: 32800 | AW26: 33020 | AX26: 33200 | AY26: 33350 | AZ26: 33460 | BA26: 33540 | BB26: 33590 | BC26: 33610 | BD26: 33610 | BE26: 33590 | BF26: 33560 | BG26: 33510 | BH26: 33470 | BI26: 33430
... A109: 94 | B109: 1310 | C109: 1370 | D109: 1330 | E109: 1450 | F109: 1480 | G109: 1480 | H109: 1480 | I109: 1400 | J109: 1740 | K109: 1830 | L109: 1920 | M109: 1940 | N109: 2000 | O109: 2070 | P109: 2050 | Q109: 2070 | R109: 1990 | S109: 2120 | T109: 2190 | U109: 2110 | V109: 2080 | W109: 2130 | X109: 2140 | Y109: 2170 | Z109: 2320 | AA109: 2420 | AB109: 2580 | AC109: 2750 | AD109: 3020 | AE109: 3300 | AF109: 3410 | AG109: 3120 | AH109: 3480 | AI109: 3730 | AJ109: 4010 | AK109: 4830 | AL109: 4900 | AM109: 4890 | AN109: 5170 | AO109: 5170 | AP109: 5420 | AQ109: 5610 | AR109: 5910 | AS109: 6150 | AT109: 6450 | AU109: 6700 | AV109: 6990 | AW109: 7320 | AX109: 7530 | AY109: 7970 | AZ109: 8340 | BA109: 8540 | BB109: 8490 | BC109: 8390 | BD109: 8410 | BE109: 8740 | BF109: 8980 | BG109: 9320 | BH109: 9460 | BI109: 9990
A110: 95 & over | B110: 2960 | C110: 3090 | D110: 3260 | E110: 3310 | F110: 3590 | G110: 3710 | H110: 3780 | I110: 3810 | J110: 3860 | K110: 4120 | L110: 4390 | M110: 4710 | N110: 4980 | O110: 5180 | P110: 5330 | Q110: 5510 | R110: 5380 | S110: 5140 | T110: 5280 | U110: 5600 | V110: 5800 | W110: 5920 | X110: 6040 | Y110: 6140 | Z110: 6230 | AA110: 6430 | AB110: 6660 | AC110: 6950 | AD110: 7320 | AE110: 7810 | AF110: 8410 | AG110: 8960 | AH110: 9140 | AI110: 9560 | AJ110: 10080 | AK110: 10690 | AL110: 11830 | AM110: 12760 | AN110: 13460 | AO110: 14210 | AP110: 14780 | AQ110: 15420 | AR110: 16050 | AS110: 16780 | AT110: 17550 | AU110: 18370 | AV110: 19220 | AW110: 20110 | AX110: 21070 | AY110: 21990 | AZ110: 23060 | BA110: 24200 | BB110: 25240 | BC110: 26030 | BD110: 26540 | BE110: 26970 | BF110: 27570 | BG110: 28250 | BH110: 29070 | BI110: 29840
A111: Female total | B111: =SUM(B$15:B$110) -> 2136250 | C111: =SUM(C$15:C$110) -> 2157380 | D111: =SUM(D$15:D$110) -> 2176330 | E111: =SUM(E$15:E$110) -> 2197940 | F111: =SUM(F$15:F$110) -> 2222910 | G111: =SUM(G$15:G$110) -> 2240420 | H111: =SUM(H$15:H$110) -> 2252990 | I111: =SUM(I$15:I$110) -> 2269940 | ... AI111: =SUM(AI$15:AI$110) -> 3047710
A114: MALE POPULATION
A115: =$A$15 -> 0 | B115: 30150 | C115: 31900 | D115: 33050 | E115: 33060 | F115: 33020 | G115: 32130 | H115: 31320 | I115: 30890 | J115: 30140 | K115: 30350 | L115: 30610 | M115: 30690 | N115: 30530 | O115: 30740 | P115: 30270 | Q115: 31310 | R115: 30520 | S115: 29280 | T115: 29270 | U115: 29840 | V115: 29850 | W115: 29850 | X115: 29830 | Y115: 29820 | Z115: 29810 | AA115: 29810 | AB115: 29830 | AC115: 29890 | AD115: 29980 | AE115: 30100 | AF115: 30270 | AG115: 30460 | AH115: 30680 | AI115: 30910 | AJ115: 31150 | AK115: 31380 | AL115: 31580 | AM115: 31750 | AN115: 31880 | AO115: 31980 | AP115: 32050 | AQ115: 32080 | AR115: 32080 | AS115: 32050 | AT115: 32010 | AU115: 31950 | AV115: 31880 | AW115: 31810 | AX115: 31750 | AY115: 31690 | AZ115: 31640 | BA115: 31610 | BB115: 31600 | BC115: 31610 | BD115: 31640 | BE115: 31690 | BF115: 31750 | BG115: 31840 | BH115: 31940 | BI115: 32050
A116: =$A$16 -> 1 | B116: 29380 | C116: 30170 | D116: 31780 | E116: 32980 | F116: 33130 | G116: 33060 | H116: 32050 | I116: 31410 | J116: 31010 | K116: 30350 | L116: 30650 | M116: 30930 | N116: 30900 | O116: 30640 | P116: 31000 | Q116: 30370 | R116: 31240 | S116: 30750 | T116: 29490 | U116: 29240 | V116: 29840 | W116: 29860 | X116: 29870 | Y116: 29860 | Z116: 29850 | AA116: 29840 | AB116: 29850 | AC116: 29880 | AD116: 29930 | AE116: 30020 | AF116: 30150 | AG116: 30310 | AH116: 30510 | AI116: 30730 | AJ116: 30970 | AK116: 31200 | AL116: 31430 | AM116: 31630 | AN116: 31810 | AO116: 31940 | AP116: 32040 | AQ116: 32110 | AR116: 32140 | AS116: 32140 | AT116: 32120 | AU116: 32080 | AV116: 32020 | AW116: 31960 | AX116: 31890 | AY116: 31830 | AZ116: 31770 | BA116: 31720 | BB116: 31690 | BC116: 31680 | BD116: 31690 | BE116: 31720 | BF116: 31770 | BG116: 31840 | BH116: 31930 | BI116: 32030
A117: =$A$17 -> 2 | B117: 29510 | C117: 29490 | D117: 30170 | E117: 31800 | F117: 33070 | G117: 33070 | H117: 32930 | I117: 31970 | J117: 31670 | K117: 31400 | L117: 30920 | M117: 31290 | N117: 31420 | O117: 31310 | P117: 31070 | Q117: 31160 | R117: 30440 | S117: 31660 | T117: 31270 | U117: 29590 | V117: 29370 | W117: 29980 | X117: 30020 | Y117: 30030 | Z117: 30030 | AA117: 30030 | AB117: 30020 | AC117: 30030 | AD117: 30060 | AE117: 30110 | AF117: 30200 | AG117: 30340 | AH117: 30500 | AI117: 30700 | AJ117: 30920 | AK117: 31160 | AL117: 31400 | AM117: 31630 | AN117: 31830 | AO117: 32010 | AP117: 32150 | AQ117: 32250 | AR117: 32310 | AS117: 32350 | AT117: 32350 | AU117: 32330 | AV117: 32290 | AW117: 32240 | AX117: 32170 | AY117: 32110 | AZ117: 32040 | BA117: 31990 | BB117: 31940 | BC117: 31920 | BD117: 31910 | BE117: 31920 | BF117: 31950 | BG117: 32000 | BH117: 32070 | BI117: 32160
A118: =$A$18 -> 3 | B118: 28800 | C118: 29680 | D118: 29550 | E118: 30280 | F118: 31860 | G118: 32950 | H118: 32970 | I118: 32960 | J118: 32220 | K118: 32020 | L118: 31970 | M118: 31570 | N118: 31850 | O118: 31860 | P118: 31920 | Q118: 31240 | R118: 31390 | S118: 31090 | T118: 32200 | U118: 31410 | V118: 29770 | W118: 29560 | X118: 30190 | Y118: 30240 | Z118: 30260 | AA118: 30260 | AB118: 30260 | AC118: 30250 | AD118: 30260 | AE118: 30290 | AF118: 30350 | AG118: 30450 | AH118: 30580 | AI118: 30750 | AJ118: 30950 | AK118: 31170 | AL118: 31410 | AM118: 31650 | AN118: 31880 | AO118: 32090 | AP118: 32260 | AQ118: 32400 | AR118: 32510 | AS118: 32580 | AT118: 32610 | AU118: 32620 | AV118: 32600 | AW118: 32560 | AX118: 32510 | AY118: 32440 | AZ118: 32380 | BA118: 32320 | BB118: 32270 | BC118: 32230 | BD118: 32200 | BE118: 32190 | BF118: 32200 | BG118: 32240 | BH118: 32290 | BI118: 32360
A119: =$A$19 -> 4 | B119: 28370 | C119: 28970 | D119: 29740 | E119: 29670 | F119: 30290 | G119: 31810 | H119: 32820 | I119: 32930 | J119: 33110 | K119: 32540 | L119: 32460 | M119: 32480 | N119: 32120 | O119: 32360 | P119: 32360 | Q119: 32020 | R119: 31360 | S119: 32140 | T119: 31840 | U119: 32380 | V119: 31630 | W119: 30010 | X119: 29820 | Y119: 30460 | Z119: 30510 | AA119: 30540 | AB119: 30550 | AC119: 30540 | AD119: 30540 | AE119: 30550 | AF119: 30580 | AG119: 30640 | AH119: 30740 | AI119: 30870 | AJ119: 31050 | AK119: 31250 | AL119: 31470 | AM119: 31710 | AN119: 31960 | AO119: 32190 | AP119: 32400 | AQ119: 32570 | AR119: 32720 | AS119: 32820 | AT119: 32890 | AU119: 32930 | AV119: 32940 | AW119: 32920 | AX119: 32890 | AY119: 32830 | AZ119: 32770 | BA119: 32710 | BB119: 32650 | BC119: 32600 | BD119: 32560 | BE119: 32540 | BF119: 32530 | BG119: 32550 | BH119: 32580 | BI119: 32640
A120: =$A$20 -> 5 | B120: 29670 | C120: 28590 | D120: 29100 | E120: 29870 | F120: 29760 | G120: 30240 | H120: 31670 | I120: 32730 | J120: 33050 | K120: 33360 | L120: 32990 | M120: 32950 | N120: 32960 | O120: 32680 | P120: 32910 | Q120: 32500 | R120: 32050 | S120: 32120 | T120: 32920 | U120: 32030 | V120: 32610 | W120: 31880 | X120: 30280 | Y120: 30100 | Z120: 30750 | AA120: 30800 | AB120: 30830 | AC120: 30840 | AD120: 30840 | AE120: 30840 | AF120: 30850 | AG120: 30890 | AH120: 30950 | AI120: 31050 | AJ120: 31180 | AK120: 31360 | AL120: 31560 | AM120: 31790 | AN120: 32030 | AO120: 32280 | AP120: 32510 | AQ120: 32720 | AR120: 32900 | AS120: 33050 | AT120: 33150 | AU120: 33230 | AV120: 33270 | AW120: 33280 | AX120: 33260 | AY120: 33230 | AZ120: 33180 | BA120: 33120 | BB120: 33060 | BC120: 33000 | BD120: 32950 | BE120: 32920 | BF120: 32890 | BG120: 32890 | BH120: 32910 | BI120: 32940
A121: =$A$21 -> 6 | B121: 30280 | C121: 29980 | D121: 28760 | E121: 29210 | F121: 29950 | G121: 29730 | H121: 30080 | I121: 31520 | J121: 32870 | K121: 33280 | L121: 33630 | M121: 33450 | N121: 33340 | O121: 33330 | P121: 33180 | Q121: 32980 | R121: 32530 | S121: 32760 | T121: 32910 | U121: 33130 | V121: 32280 | W121: 32880 | X121: 32170 | Y121: 30580 | Z121: 30410 | AA121: 31060 | AB121: 31120 | AC121: 31150 | AD121: 31160 | AE121: 31160 | AF121: 31160 | AG121: 31180 | AH121: 31210 | AI121: 31280 | AJ121: 31380 | AK121: 31520 | AL121: 31690 | AM121: 31900 | AN121: 32130 | AO121: 32370 | AP121: 32620 | AQ121: 32860 | AR121: 33070 | AS121: 33250 | AT121: 33400 | AU121: 33510 | AV121: 33580 | AW121: 33620 | AX121: 33640 | AY121: 33620 | AZ121: 33590 | BA121: 33540 | BB121: 33490 | BC121: 33430 | BD121: 33380 | BE121: 33330 | BF121: 33290 | BG121: 33270 | BH121: 33270 | BI121: 33290
A122: =$A$22 -> 7 | B122: 29500 | C122: 30570 | D122: 30180 | E122: 28890 | F122: 29340 | G122: 29910 | H122: 29610 | I122: 29960 | J122: 31670 | K122: 33060 | L122: 33510 | M122: 33970 | N122: 33780 | O122: 33750 | P122: 33740 | Q122: 33350 | R122: 33010 | S122: 33250 | T122: 33470 | U122: 33130 | V122: 33390 | W122: 32560 | X122: 33180 | Y122: 32480 | Z122: 30900 | AA122: 30730 | AB122: 31390 | AC122: 31450 | AD122: 31480 | AE122: 31490 | AF122: 31500 | AG122: 31500 | AH122: 31520 | AI122: 31560 | AJ122: 31620 | AK122: 31720 | AL122: 31870 | AM122: 32040 | AN122: 32250 | AO122: 32480 | AP122: 32730 | AQ122: 32980 | AR122: 33220 | AS122: 33430 | AT122: 33620 | AU122: 33770 | AV122: 33880 | AW122: 33960 | AX122: 34000 | AY122: 34010 | AZ122: 34000 | BA122: 33970 | BB122: 33930 | BC122: 33870 | BD122: 33820 | BE122: 33770 | BF122: 33720 | BG122: 33690 | BH122: 33670 | BI122: 33670
A123: =$A$23 -> 8 | B123: 29960 | C123: 29810 | D123: 30860 | E123: 30370 | F123: 29120 | G123: 29410 | H123: 29840 | I123: 29550 | J123: 30110 | K123: 31880 | L123: 33360 | M123: 33860 | N123: 34200 | O123: 34170 | P123: 34210 | Q123: 33870 | R123: 33350 | S123: 33740 | T123: 34050 | U123: 33700 | V123: 33400 | W123: 33680 | X123: 32870 | Y123: 33500 | Z123: 32810 | AA123: 31230 | AB123: 31060 | AC123: 31720 | AD123: 31790 | AE123: 31820 | AF123: 31840 | AG123: 31840 | AH123: 31850 | AI123: 31870 | AJ123: 31910 | AK123: 31980 | AL123: 32080 | AM123: 32220 | AN123: 32400 | AO123: 32610 | AP123: 32850 | AQ123: 33100 | AR123: 33350 | AS123: 33590 | AT123: 33810 | AU123: 33990 | AV123: 34140 | AW123: 34260 | AX123: 34340 | AY123: 34380 | AZ123: 34400 | BA123: 34390 | BB123: 34360 | BC123: 34320 | BD123: 34270 | BE123: 34220 | BF123: 34160 | BG123: 34120 | BH123: 34090 | BI123: 34080
A124: =$A$24 -> 9 | B124: 29820 | C124: 30270 | D124: 30090 | E124: 31080 | F124: 30610 | G124: 29220 | H124: 29330 | I124: 29810 | J124: 29700 | K124: 30340 | L124: 32240 | M124: 33630 | N124: 34150 | O124: 34610 | P124: 34590 | Q124: 34310 | R124: 33920 | S124: 34030 | T124: 34600 | U124: 34290 | V124: 33970 | W124: 33690 | X124: 33990 | Y124: 33190 | Z124: 33830 | AA124: 33140 | AB124: 31570 | AC124: 31400 | AD124: 32060 | AE124: 32130 | AF124: 32170 | AG124: 32180 | AH124: 32190 | AI124: 32200 | AJ124: 32220 | AK124: 32260 | AL124: 32340 | AM124: 32440 | AN124: 32590 | AO124: 32770 | AP124: 32980 | AQ124: 33220 | AR124: 33470 | AS124: 33720 | AT124: 33970 | AU124: 34180 | AV124: 34370 | AW124: 34530 | AX124: 34640 | AY124: 34720 | AZ124: 34770 | BA124: 34790 | BB124: 34780 | BC124: 34760 | BD124: 34720 | BE124: 34670 | BF124: 34620 | BG124: 34570 | BH124: 34530 | BI124: 34500
...

Sheet Population Treasury
A1: RESIDENT POPULATION OF NEW ZEALAND, BY SINGLE YEAR OF AGE AND GENDER, AS AT 30 JUNE, THAT MATCHES HOUSEHOLD LABOUR FORCE SURVEY (HLFS) HISTORY AND TREASURY"S HLFS-BASED FORECASTS
A2: Year ended 30 June | B2: 2005/06 | C2: 2006/07 | D2: 2007/08 | E2: 2008/09 | F2: 2009/10 | G2: 2010/11 | H2: 2011/12 | I2: 2012/13 | J2: 2013/14 | K2: 2014/15 | L2: 2015/16 | M2: 2016/17 | N2: 2017/18 | O2: 2018/19 | P2: 2019/20 | Q2: 2020/21 | R2: 2021/22 | S2: 2022/23 | T2: 2023/24 | U2: 2024/25 | V2: 2025/26 | W2: 2026/27 | X2: 2027/28 | Y2: 2028/29 | Z2: 2029/30 | AA2: 2030/31 | AB2: 2031/32 | AC2: 2032/33 | AD2: 2033/34 | AE2: 2034/35 | AF2: 2035/36 | AG2: 2036/37 | AH2: 2037/38 | AI2: 2038/39 | AJ2: 2039/40 | AK2: 2040/41 | AL2: 2041/42 | AM2: 2042/43 | AN2: 2043/44 | AO2: 2044/45 | AP2: 2045/46 | AQ2: 2046/47 | AR2: 2047/48 | AS2: 2048/49 | AT2: 2049/50 | AU2: 2050/51 | AV2: 2051/52 | AW2: 2052/53 | AX2: 2053/54 | AY2: 2054/55 | AZ2: 2055/56 | BA2: 2056/57 | BB2: 2057/58 | BC2: 2058/59 | BD2: 2059/60 | BE2: 2060/61 | BF2: 2061/62 | BG2: 2062/63 | BH2: 2063/64 | BI2: 2064/65
B3: 2006 | C3: 2007 | D3: 2008 | E3: 2009 | F3: 2010 | G3: 2011 | H3: 2012 | I3: 2013 | J3: 2014 | K3: 2015 | L3: 2016 | M3: 2017 | N3: 2018 | O3: 2019 | P3: 2020 | Q3: 2021 | R3: 2022 | S3: 2023 | T3: 2024 | U3: 2025 | V3: 2026 | W3: 2027 | X3: 2028 | Y3: 2029 | Z3: 2030 | AA3: 2031 | AB3: 2032 | AC3: 2033 | AD3: 2034 | AE3: 2035 | AF3: 2036 | AG3: 2037 | AH3: 2038 | AI3: 2039 | AJ3: 2040 | AK3: 2041 | AL3: 2042 | AM3: 2043 | AN3: 2044 | AO3: 2045 | AP3: 2046 | AQ3: 2047 | AR3: 2048 | AS3: 2049 | AT3: 2050 | AU3: 2051 | AV3: 2052 | AW3: 2053 | AX3: 2054 | AY3: 2055 | AZ3: 2056 | BA3: 2057 | BB3: 2058 | BC3: 2059 | BD3: 2060 | BE3: 2061 | BF3: 2062 | BG3: 2063 | BH3: 2064 | BI3: 2065
A4: Population (millions) | B4: =SUM(B$15:B$110,B$115:B$210)/1000000 -> 4.1669 | C4: =SUM(C$15:C$110,C$115:C$210)/1000000 -> 4.212 | D4: =SUM(D$15:D$110,D$115:D$210)/1000000 -> 4.2489 | E4: =SUM(E$15:E$110,E$115:E$210)/1000000 -> 4.2865 | F4: =SUM(F$15:F$110,F$115:F$210)/1000000 -> 4.3365 | G4: =SUM(G$15:G$110,G$115:G$210)/1000000 -> 4.3758 | H4: =SUM(H$15:H$110,H$115:H$210)/1000000 -> 4.4015 | I4: =SUM(I$15:I$110,I$115:I$210)/1000000 -> 4.4299 | ... BI4: =SUM(BI$15:BI$110,BI$115:BI$210)/1000000 -> 7.36473
A5: Annual growth (%) | C5: =C$4/B$4-1 -> 0.010823394 | D5: =D$4/C$4-1 -> 0.0087606838 | E5: =E$4/D$4-1 -> 0.0088493492 | F5: =F$4/E$4-1 -> 0.011664528 | G5: =G$4/F$4-1 -> 0.0090626081 | H5: =H$4/G$4-1 -> 0.0058732118 | I5: =I$4/H$4-1 -> 0.0064523458 | J5: =J$4/I$4-1 -> 0.013160568 | ... BI5: =BI$4/BH$4-1 -> 0.0059292586
A6: Working-age popn (15+, millions) | B6: =SUM(B$30:B$110,B$130:B$210)/1000000 -> 3.2251 | C6: =SUM(C$30:C$110,C$130:C$210)/1000000 -> 3.2726 | D6: =SUM(D$30:D$110,D$130:D$210)/1000000 -> 3.3046 | E6: =SUM(E$30:E$110,E$130:E$210)/1000000 -> 3.3358 | F6: =SUM(F$30:F$110,F$130:F$210)/1000000 -> 3.3767 | G6: =SUM(G$30:G$110,G$130:G$210)/1000000 -> 3.4116 | H6: =SUM(H$30:H$110,H$130:H$210)/1000000 -> 3.437 | I6: =SUM(I$30:I$110,I$130:I$210)/1000000 -> 3.4639 | ... BI6: =SUM(BI$30:BI$110,BI$130:BI$210)/1000000 -> 6.2615748
A7: Minors' popn (0-14, millions) | B7: =SUM(B$15:B$29,B$115:B$129)/1000000 -> 0.9418 | C7: =SUM(C$15:C$29,C$115:C$129)/1000000 -> 0.9394 | D7: =SUM(D$15:D$29,D$115:D$129)/1000000 -> 0.9443 | E7: =SUM(E$15:E$29,E$115:E$129)/1000000 -> 0.9507 | F7: =SUM(F$15:F$29,F$115:F$129)/1000000 -> 0.9598 | G7: =SUM(G$15:G$29,G$115:G$129)/1000000 -> 0.9642 | H7: =SUM(H$15:H$29,H$115:H$129)/1000000 -> 0.9645 | I7: =SUM(I$15:I$29,I$115:I$129)/1000000 -> 0.966 | ... BI7: =SUM(BI$15:BI$29,BI$115:BI$129)/1000000 -> 1.1031552
A8: Net Migration (thousands) - Treasury | U8: ='Economic Forecasts'!W$17 -> 32.9 | V8: ='Economic Forecasts'!X$17 -> 38.2 | W8: ='Economic Forecasts'!Y$17 -> 39.5 | X8: ='Economic Forecasts'!Z$17 -> 39.9 | Y8: ='Economic Forecasts'!AA$17 -> 40 | Z8: =MAX(Y$8-0.5,Z$9) -> 39.5 | AA8: =MAX(Z$8-0.5,AA$9) -> 39 | AB8: =MAX(AA$8-0.5,AB$9) -> 38.5 | AC8: =MAX(AB$8-0.5,AC$9) -> 38 | AD8: =MAX(AC$8-0.5,AD$9) -> 38.3 | AE8: =MAX(AD$8-0.5,AE$9) -> 38.5 | AF8: =MAX(AE$8-0.5,AF$9) -> 38.8 | AG8: =MAX(AF$8-0.5,AG$9) -> 39 | ... BI8: =MAX(BH$8-0.5,BI$9) -> 46
A9: Net Migration (thousands) - Statistics NZ | U9: 25 | V9: 30 | W9: 32.5 | X9: 34.5 | Y9: 36 | Z9: 37 | AA9: =Z9+0.5 -> 37.5 | AB9: =AA9+0.3 -> 37.8 | AC9: =AB9+0.2 -> 38 | AD9: =AC9+0.3 -> 38.3 | AE9: =AD9+0.2 -> 38.5 | AF9: =AE9+0.3 -> 38.8 | AG9: =AF9+0.2 -> 39 | AH9: =AG9+0.3 -> 39.3 | AI9: =AH9+0.2 -> 39.5 | AJ9: =AI9+0.3 -> 39.8 | AK9: =AJ9+0.2 -> 40 | AL9: =AK9+0.3 -> 40.3 | AM9: =AL9+0.2 -> 40.5 | AN9: =AM9+0.3 -> 40.8 | AO9: =AN9+0.2 -> 41 | AP9: =AO9+0.3 -> 41.3 | AQ9: =AP9+0.2 -> 41.5 | AR9: =AQ9+0.3 -> 41.8 | AS9: =AR9+0.2 -> 42 | AT9: =AS9+0.3 -> 42.3 | AU9: =AT9+0.2 -> 42.5 | AV9: =AU9+0.3 -> 42.8 | AW9: =AV9+0.2 -> 43 | AX9: =AW9+0.3 -> 43.3 | AY9: =AX9+0.2 -> 43.5 | AZ9: =AY9+0.3 -> 43.8 | BA9: =AZ9+0.2 -> 44 | BB9: =BA9+0.3 -> 44.3 | BC9: =BB9+0.2 -> 44.5 | BD9: =BC9+0.3 -> 44.8 | BE9: =BD9+0.2 -> 45 | BF9: =BE9+0.3 -> 45.3 | BG9: =BF9+0.2 -> 45.5 | BH9: =BG9+0.3 -> 45.8 | BI9: =BH9+0.2 -> 46
A10: Net Migration by age and gender group (percentages are based on June-end years between 2001/02 and 2022/23, where net migration was at least 10,000)
A11: Age Group (years) | B11: 0 to 4 | C11: 5 to 9 | D11: 10 to 14 | E11: 15 to 19 | F11: 20 to 24 | G11: 25 to 29 | H11: 30 to 34 | I11: 35 to 39 | J11: 40 to 44 | K11: 45 to 49 | L11: 50 to 54 | M11: 55 to 59 | N11: 60 to 64 | O11: 65 to 69 | P11: 70 to 74 | Q11: 75 to 79 | R11: 80 to 84 | S11: 85 to 89 | T11: 90 & over | U11: TOTAL
A12: Female | B12: 0.026425591 | C12: 0.041234733 | D12: 0.04015632 | E12: 0.055410759 | F12: -0.0070268329 | G12: 0.099773874 | H12: 0.10249018 | I12: 0.064931741 | J12: 0.036680817 | K12: 0.0096258135 | L12: 0.0025606803 | M12: 0.01051327 | N12: 0.0153957 | O12: 0.0078155333 | P12: 0.0031598032 | Q12: 0.0017419225 | R12: 0.00095729348 | S12: 0.00031786944 | T12: 0.0003014299 | U12: =SUM($B$12:$T$12) -> 0.5124665
A13: Male | B13: 0.030037309 | C13: 0.044282169 | D13: 0.042377857 | E13: 0.068621463 | F13: -0.010238044 | G13: 0.04588582 | H13: 0.093818368 | I13: 0.07100718 | J13: 0.046829162 | K13: 0.018292934 | L13: 0.0041365914 | M13: 0.0045830699 | N13: 0.012758722 | O13: 0.0088155106 | P13: 0.0035659477 | Q13: 0.0016009593 | R13: 0.00048177268 | S13: 0.00038055896 | T13: 0.0002994967 | U13: =SUM($B$13:$T$13) -> 0.48753685
A14: FEMALE POPULATION
A15: 0 | B15: ='Statistics NZ'!B$15*('Economic Forecasts'!D$10-'Economic Forecasts'!D$9)*1000000/SUM('Statistics NZ'!B$15:B$29,'Statistics NZ'!B$115:B$129) -> 30650.829 | C15: ='Statistics NZ'!C$15*('Economic Forecasts'!E$10-'Economic Forecasts'!E$9)*1000000/SUM('Statistics NZ'!C$15:C$29,'Statistics NZ'!C$115:C$129) -> 31861.396 | D15: ='Statistics NZ'!D$15*('Economic Forecasts'!F$10-'Economic Forecasts'!F$9)*1000000/SUM('Statistics NZ'!D$15:D$29,'Statistics NZ'!D$115:D$129) -> 33068.584 | E15: ='Statistics NZ'!E$15*('Economic Forecasts'!G$10-'Economic Forecasts'!G$9)*1000000/SUM('Statistics NZ'!E$15:E$29,'Statistics NZ'!E$115:E$129) -> 32524.836 | F15: ='Statistics NZ'!F$15*('Economic Forecasts'!H$10-'Economic Forecasts'!H$9)*1000000/SUM('Statistics NZ'!F$15:F$29,'Statistics NZ'!F$115:F$129) -> 33302.462 | G15: ='Statistics NZ'!G$15*('Economic Forecasts'!I$10-'Economic Forecasts'!I$9)*1000000/SUM('Statistics NZ'!G$15:G$29,'Statistics NZ'!G$115:G$129) -> 32471.384 | H15: ='Statistics NZ'!H$15*('Economic Forecasts'!J$10-'Economic Forecasts'!J$9)*1000000/SUM('Statistics NZ'!H$15:H$29,'Statistics NZ'!H$115:H$129) -> 31676.13 | I15: ='Statistics NZ'!I$15*('Economic Forecasts'!K$10-'Economic Forecasts'!K$9)*1000000/SUM('Statistics NZ'!I$15:I$29,'Statistics NZ'!I$115:I$129) -> 31218.895 | ... T15: ='Statistics NZ'!T$15*('Economic Forecasts'!V$10-'Economic Forecasts'!V$9)*1000000/SUM('Statistics NZ'!T$15:T$29,'Statistics NZ'!T$115:T$129) -> 29554.175 | U15: =SUM('Statistics NZ'!U$15,$B$12/5*(U$8-U$9)*1000)*('Economic Forecasts'!W$10-'Economic Forecasts'!W$9)*1000000/SUM('Statistics NZ'!U$15:U$29,'Statistics NZ'!U$115:U$129,SUM($B$12:$D$13)*(U$8-U$9)*1000) -> 30145.243 | V15: =SUM('Statistics NZ'!V$15,$B$12/5*(V$8-V$9)*1000)*('Economic Forecasts'!X$10-'Economic Forecasts'!X$9)*1000000/SUM('Statistics NZ'!V$15:V$29,'Statistics NZ'!V$115:V$129,SUM($B$12:$D$13)*(V$8-V$9)*1000) -> 30501.17 | W15: =SUM('Statistics NZ'!W$15,$B$12/5*(W$8-W$9)*1000)*('Economic Forecasts'!Y$10-'Economic Forecasts'!Y$9)*1000000/SUM('Statistics NZ'!W$15:W$29,'Statistics NZ'!W$115:W$129,SUM($B$12:$D$13)*(W$8-W$9)*1000) -> 30881.159 | X15: =SUM('Statistics NZ'!X$15,$B$12/5*(X$8-X$9)*1000)*('Economic Forecasts'!Z$10-'Economic Forecasts'!Z$9)*1000000/SUM('Statistics NZ'!X$15:X$29,'Statistics NZ'!X$115:X$129,SUM($B$12:$D$13)*(X$8-X$9)*1000) -> 31254.297 | Y15: =SUM('Statistics NZ'!Y$15,$B$12/5*(Y$8-Y$9)*1000)*('Economic Forecasts'!AA$10-'Economic Forecasts'!AA$9)*1000000/SUM('Statistics NZ'!Y$15:Y$29,'Statistics NZ'!Y$115:Y$129,SUM($B$12:$D$13)*(Y$8-Y$9)*1000) -> 31579.403 | Z15: =SUM(Y$15,'Statistics NZ'!Z$15-'Statistics NZ'!Y$15,$B$12/5*(Z$8-Z$9)*1000) -> 31582.616 | AA15: =SUM(Z$15,'Statistics NZ'!AA$15-'Statistics NZ'!Z$15,$B$12/5*(AA$8-AA$9)*1000) -> 31600.544 | AB15: =SUM(AA$15,'Statistics NZ'!AB$15-'Statistics NZ'!AA$15,$B$12/5*(AB$8-AB$9)*1000) -> 31624.243 | AC15: =SUM(AB$15,'Statistics NZ'!AC$15-'Statistics NZ'!AB$15,$B$12/5*(AC$8-AC$9)*1000) -> 31674.243 | AD15: =SUM(AC$15,'Statistics NZ'!AD$15-'Statistics NZ'!AC$15,$B$12/5*(AD$8-AD$9)*1000) -> 31754.243 | AE15: =SUM(AD$15,'Statistics NZ'!AE$15-'Statistics NZ'!AD$15,$B$12/5*(AE$8-AE$9)*1000) -> 31874.243 | AF15: =SUM(AE$15,'Statistics NZ'!AF$15-'Statistics NZ'!AE$15,$B$12/5*(AF$8-AF$9)*1000) -> 32034.243 | AG15: =SUM(AF$15,'Statistics NZ'!AG$15-'Statistics NZ'!AF$15,$B$12/5*(AG$8-AG$9)*1000) -> 32214.243 | ... BI15: =SUM(BH$15,'Statistics NZ'!BI$15-'Statistics NZ'!BH$15,$B$12/5*(BI$8-BI$9)*1000) -> 33714.243
A16: 1 | B16: ='Statistics NZ'!B$16*('Economic Forecasts'!D$10-'Economic Forecasts'!D$9)*1000000/SUM('Statistics NZ'!B$15:B$29,'Statistics NZ'!B$115:B$129) -> 29675.431 | C16: ='Statistics NZ'!C$16*('Economic Forecasts'!E$10-'Economic Forecasts'!E$9)*1000000/SUM('Statistics NZ'!C$15:C$29,'Statistics NZ'!C$115:C$129) -> 30406.922 | D16: ='Statistics NZ'!D$16*('Economic Forecasts'!F$10-'Economic Forecasts'!F$9)*1000000/SUM('Statistics NZ'!D$15:D$29,'Statistics NZ'!D$115:D$129) -> 31750.481 | E16: ='Statistics NZ'!E$16*('Economic Forecasts'!G$10-'Economic Forecasts'!G$9)*1000000/SUM('Statistics NZ'!E$15:E$29,'Statistics NZ'!E$115:E$129) -> 32978.474 | F16: ='Statistics NZ'!F$16*('Economic Forecasts'!H$10-'Economic Forecasts'!H$9)*1000000/SUM('Statistics NZ'!F$15:F$29,'Statistics NZ'!F$115:F$129) -> 32573.211 | G16: ='Statistics NZ'!G$16*('Economic Forecasts'!I$10-'Economic Forecasts'!I$9)*1000000/SUM('Statistics NZ'!G$15:G$29,'Statistics NZ'!G$115:G$129) -> 33307.784 | H16: ='Statistics NZ'!H$16*('Economic Forecasts'!J$10-'Economic Forecasts'!J$9)*1000000/SUM('Statistics NZ'!H$15:H$29,'Statistics NZ'!H$115:H$129) -> 32481.815 | I16: ='Statistics NZ'!I$16*('Economic Forecasts'!K$10-'Economic Forecasts'!K$9)*1000000/SUM('Statistics NZ'!I$15:I$29,'Statistics NZ'!I$115:I$129) -> 31835.408 | ... T16: ='Statistics NZ'!T$16*('Economic Forecasts'!V$10-'Economic Forecasts'!V$9)*1000000/SUM('Statistics NZ'!T$15:T$29,'Statistics NZ'!T$115:T$129) -> 29437.318 | U16: =SUM('Statistics NZ'!U$16,$B$12/5*(U$8-U$9)*1000)*('Economic Forecasts'!W$10-'Economic Forecasts'!W$9)*1000000/SUM('Statistics NZ'!U$15:U$29,'Statistics NZ'!U$115:U$129,SUM($B$12:$D$13)*(U$8-U$9)*1000) -> 29623.695 | V16: =SUM('Statistics NZ'!V$16,$B$12/5*(V$8-V$9)*1000)*('Economic Forecasts'!X$10-'Economic Forecasts'!X$9)*1000000/SUM('Statistics NZ'!V$15:V$29,'Statistics NZ'!V$115:V$129,SUM($B$12:$D$13)*(V$8-V$9)*1000) -> 30490.404 | W16: =SUM('Statistics NZ'!W$16,$B$12/5*(W$8-W$9)*1000)*('Economic Forecasts'!Y$10-'Economic Forecasts'!Y$9)*1000000/SUM('Statistics NZ'!W$15:W$29,'Statistics NZ'!W$115:W$129,SUM($B$12:$D$13)*(W$8-W$9)*1000) -> 30902.97 | X16: =SUM('Statistics NZ'!X$16,$B$12/5*(X$8-X$9)*1000)*('Economic Forecasts'!Z$10-'Economic Forecasts'!Z$9)*1000000/SUM('Statistics NZ'!X$15:X$29,'Statistics NZ'!X$115:X$129,SUM($B$12:$D$13)*(X$8-X$9)*1000) -> 31298.475 | Y16: =SUM('Statistics NZ'!Y$16,$B$12/5*(Y$8-Y$9)*1000)*('Economic Forecasts'!AA$10-'Economic Forecasts'!AA$9)*1000000/SUM('Statistics NZ'!Y$15:Y$29,'Statistics NZ'!Y$115:Y$129,SUM($B$12:$D$13)*(Y$8-Y$9)*1000) -> 31635.254 | Z16: =SUM(Y$16,'Statistics NZ'!Z$16-'Statistics NZ'!Y$16,$B$12/5*(Z$8-Z$9)*1000) -> 31638.467 | AA16: =SUM(Z$16,'Statistics NZ'!AA$16-'Statistics NZ'!Z$16,$B$12/5*(AA$8-AA$9)*1000) -> 31646.395 | AB16: =SUM(AA$16,'Statistics NZ'!AB$16-'Statistics NZ'!AA$16,$B$12/5*(AB$8-AB$9)*1000) -> 31650.094 | AC16: =SUM(AB$16,'Statistics NZ'!AC$16-'Statistics NZ'!AB$16,$B$12/5*(AC$8-AC$9)*1000) -> 31680.094 | AD16: =SUM(AC$16,'Statistics NZ'!AD$16-'Statistics NZ'!AC$16,$B$12/5*(AD$8-AD$9)*1000) -> 31730.094 | AE16: =SUM(AD$16,'Statistics NZ'!AE$16-'Statistics NZ'!AD$16,$B$12/5*(AE$8-AE$9)*1000) -> 31810.094 | AF16: =SUM(AE$16,'Statistics NZ'!AF$16-'Statistics NZ'!AE$16,$B$12/5*(AF$8-AF$9)*1000) -> 31930.094 | AG16: =SUM(AF$16,'Statistics NZ'!AG$16-'Statistics NZ'!AF$16,$B$12/5*(AG$8-AG$9)*1000) -> 32090.094 | ... BI16: =SUM(BH$16,'Statistics NZ'!BI$16-'Statistics NZ'!BH$16,$B$12/5*(BI$8-BI$9)*1000) -> 33710.094
A17: 2 | B17: ='Statistics NZ'!B$17*('Economic Forecasts'!D$10-'Economic Forecasts'!D$9)*1000000/SUM('Statistics NZ'!B$15:B$29,'Statistics NZ'!B$115:B$129) -> 29876.872 | C17: ='Statistics NZ'!C$17*('Economic Forecasts'!E$10-'Economic Forecasts'!E$9)*1000000/SUM('Statistics NZ'!C$15:C$29,'Statistics NZ'!C$115:C$129) -> 29616.448 | D17: ='Statistics NZ'!D$17*('Economic Forecasts'!F$10-'Economic Forecasts'!F$9)*1000000/SUM('Statistics NZ'!D$15:D$29,'Statistics NZ'!D$115:D$129) -> 30442.922 | E17: ='Statistics NZ'!E$17*('Economic Forecasts'!G$10-'Economic Forecasts'!G$9)*1000000/SUM('Statistics NZ'!E$15:E$29,'Statistics NZ'!E$115:E$129) -> 31881.302 | F17: ='Statistics NZ'!F$17*('Economic Forecasts'!H$10-'Economic Forecasts'!H$9)*1000000/SUM('Statistics NZ'!F$15:F$29,'Statistics NZ'!F$115:F$129) -> 33122.792 | G17: ='Statistics NZ'!G$17*('Economic Forecasts'!I$10-'Economic Forecasts'!I$9)*1000000/SUM('Statistics NZ'!G$15:G$29,'Statistics NZ'!G$115:G$129) -> 32577.257 | H17: ='Statistics NZ'!H$17*('Economic Forecasts'!J$10-'Economic Forecasts'!J$9)*1000000/SUM('Statistics NZ'!H$15:H$29,'Statistics NZ'!H$115:H$129) -> 33192.09 | I17: ='Statistics NZ'!I$17*('Economic Forecasts'!K$10-'Economic Forecasts'!K$9)*1000000/SUM('Statistics NZ'!I$15:I$29,'Statistics NZ'!I$115:I$129) -> 32505.067 | ... T17: ='Statistics NZ'!T$17*('Economic Forecasts'!V$10-'Economic Forecasts'!V$9)*1000000/SUM('Statistics NZ'!T$15:T$29,'Statistics NZ'!T$115:T$129) -> 32348.118 | U17: =SUM('Statistics NZ'!U$17,$B$12/5*(U$8-U$9)*1000)*('Economic Forecasts'!W$10-'Economic Forecasts'!W$9)*1000000/SUM('Statistics NZ'!U$15:U$29,'Statistics NZ'!U$115:U$129,SUM($B$12:$D$13)*(U$8-U$9)*1000) -> 29613.051 | V17: =SUM('Statistics NZ'!V$17,$B$12/5*(V$8-V$9)*1000)*('Economic Forecasts'!X$10-'Economic Forecasts'!X$9)*1000000/SUM('Statistics NZ'!V$15:V$29,'Statistics NZ'!V$115:V$129,SUM($B$12:$D$13)*(V$8-V$9)*1000) -> 30070.565 | W17: =SUM('Statistics NZ'!W$17,$B$12/5*(W$8-W$9)*1000)*('Economic Forecasts'!Y$10-'Economic Forecasts'!Y$9)*1000000/SUM('Statistics NZ'!W$15:W$29,'Statistics NZ'!W$115:W$129,SUM($B$12:$D$13)*(W$8-W$9)*1000) -> 31001.119 | X17: =SUM('Statistics NZ'!X$17,$B$12/5*(X$8-X$9)*1000)*('Economic Forecasts'!Z$10-'Economic Forecasts'!Z$9)*1000000/SUM('Statistics NZ'!X$15:X$29,'Statistics NZ'!X$115:X$129,SUM($B$12:$D$13)*(X$8-X$9)*1000) -> 31431.009 | Y17: =SUM('Statistics NZ'!Y$17,$B$12/5*(Y$8-Y$9)*1000)*('Economic Forecasts'!AA$10-'Economic Forecasts'!AA$9)*1000000/SUM('Statistics NZ'!Y$15:Y$29,'Statistics NZ'!Y$115:Y$129,SUM($B$12:$D$13)*(Y$8-Y$9)*1000) -> 31791.637 | Z17: =SUM(Y$17,'Statistics NZ'!Z$17-'Statistics NZ'!Y$17,$B$12/5*(Z$8-Z$9)*1000) -> 31804.85 | AA17: =SUM(Z$17,'Statistics NZ'!AA$17-'Statistics NZ'!Z$17,$B$12/5*(AA$8-AA$9)*1000) -> 31812.777 | AB17: =SUM(AA$17,'Statistics NZ'!AB$17-'Statistics NZ'!AA$17,$B$12/5*(AB$8-AB$9)*1000) -> 31806.477 | AC17: =SUM(AB$17,'Statistics NZ'!AC$17-'Statistics NZ'!AB$17,$B$12/5*(AC$8-AC$9)*1000) -> 31816.477 | AD17: =SUM(AC$17,'Statistics NZ'!AD$17-'Statistics NZ'!AC$17,$B$12/5*(AD$8-AD$9)*1000) -> 31846.477 | AE17: =SUM(AD$17,'Statistics NZ'!AE$17-'Statistics NZ'!AD$17,$B$12/5*(AE$8-AE$9)*1000) -> 31896.477 | AF17: =SUM(AE$17,'Statistics NZ'!AF$17-'Statistics NZ'!AE$17,$B$12/5*(AF$8-AF$9)*1000) -> 31986.477 | AG17: =SUM(AF$17,'Statistics NZ'!AG$17-'Statistics NZ'!AF$17,$B$12/5*(AG$8-AG$9)*1000) -> 32106.477 | ... BI17: =SUM(BH$17,'Statistics NZ'!BI$17-'Statistics NZ'!BH$17,$B$12/5*(BI$8-BI$9)*1000) -> 33836.477
A18: 3 | B18: ='Statistics NZ'!B$18*('Economic Forecasts'!D$10-'Economic Forecasts'!D$9)*1000000/SUM('Statistics NZ'!B$15:B$29,'Statistics NZ'!B$115:B$129) -> 28954.484 | C18: ='Statistics NZ'!C$18*('Economic Forecasts'!E$10-'Economic Forecasts'!E$9)*1000000/SUM('Statistics NZ'!C$15:C$29,'Statistics NZ'!C$115:C$129) -> 29785.082 | D18: ='Statistics NZ'!D$18*('Economic Forecasts'!F$10-'Economic Forecasts'!F$9)*1000000/SUM('Statistics NZ'!D$15:D$29,'Statistics NZ'!D$115:D$129) -> 29620.425 | E18: ='Statistics NZ'!E$18*('Economic Forecasts'!G$10-'Economic Forecasts'!G$9)*1000000/SUM('Statistics NZ'!E$15:E$29,'Statistics NZ'!E$115:E$129) -> 30499.286 | F18: ='Statistics NZ'!F$18*('Economic Forecasts'!H$10-'Economic Forecasts'!H$9)*1000000/SUM('Statistics NZ'!F$15:F$29,'Statistics NZ'!F$115:F$129) -> 32002.493 | G18: ='Statistics NZ'!G$18*('Economic Forecasts'!I$10-'Economic Forecasts'!I$9)*1000000/SUM('Statistics NZ'!G$15:G$29,'Statistics NZ'!G$115:G$129) -> 33127.799 | H18: ='Statistics NZ'!H$18*('Economic Forecasts'!J$10-'Economic Forecasts'!J$9)*1000000/SUM('Statistics NZ'!H$15:H$29,'Statistics NZ'!H$115:H$129) -> 32513.618 | I18: ='Statistics NZ'!I$18*('Economic Forecasts'!K$10-'Economic Forecasts'!K$9)*1000000/SUM('Statistics NZ'!I$15:I$29,'Statistics NZ'!I$115:I$129) -> 33291.652 | ... T18: ='Statistics NZ'!T$18*('Economic Forecasts'!V$10-'Economic Forecasts'!V$9)*1000000/SUM('Statistics NZ'!T$15:T$29,'Statistics NZ'!T$115:T$129) -> 32231.261 | U18: =SUM('Statistics NZ'!U$18,$B$12/5*(U$8-U$9)*1000)*('Economic Forecasts'!W$10-'Economic Forecasts'!W$9)*1000000/SUM('Statistics NZ'!U$15:U$29,'Statistics NZ'!U$115:U$129,SUM($B$12:$D$13)*(U$8-U$9)*1000) -> 32582.684 | V18: =SUM('Statistics NZ'!V$18,$B$12/5*(V$8-V$9)*1000)*('Economic Forecasts'!X$10-'Economic Forecasts'!X$9)*1000000/SUM('Statistics NZ'!V$15:V$29,'Statistics NZ'!V$115:V$129,SUM($B$12:$D$13)*(V$8-V$9)*1000) -> 30113.625 | W18: =SUM('Statistics NZ'!W$18,$B$12/5*(W$8-W$9)*1000)*('Economic Forecasts'!Y$10-'Economic Forecasts'!Y$9)*1000000/SUM('Statistics NZ'!W$15:W$29,'Statistics NZ'!W$115:W$129,SUM($B$12:$D$13)*(W$8-W$9)*1000) -> 30641.237 | X18: =SUM('Statistics NZ'!X$18,$B$12/5*(X$8-X$9)*1000)*('Economic Forecasts'!Z$10-'Economic Forecasts'!Z$9)*1000000/SUM('Statistics NZ'!X$15:X$29,'Statistics NZ'!X$115:X$129,SUM($B$12:$D$13)*(X$8-X$9)*1000) -> 31596.676 | Y18: =SUM('Statistics NZ'!Y$18,$B$12/5*(Y$8-Y$9)*1000)*('Economic Forecasts'!AA$10-'Economic Forecasts'!AA$9)*1000000/SUM('Statistics NZ'!Y$15:Y$29,'Statistics NZ'!Y$115:Y$129,SUM($B$12:$D$13)*(Y$8-Y$9)*1000) -> 31992.7 | Z18: =SUM(Y$18,'Statistics NZ'!Z$18-'Statistics NZ'!Y$18,$B$12/5*(Z$8-Z$9)*1000) -> 32025.913 | AA18: =SUM(Z$18,'Statistics NZ'!AA$18-'Statistics NZ'!Z$18,$B$12/5*(AA$8-AA$9)*1000) -> 32043.841 | AB18: =SUM(AA$18,'Statistics NZ'!AB$18-'Statistics NZ'!AA$18,$B$12/5*(AB$8-AB$9)*1000) -> 32037.54 | AC18: =SUM(AB$18,'Statistics NZ'!AC$18-'Statistics NZ'!AB$18,$B$12/5*(AC$8-AC$9)*1000) -> 32037.54 | AD18: =SUM(AC$18,'Statistics NZ'!AD$18-'Statistics NZ'!AC$18,$B$12/5*(AD$8-AD$9)*1000) -> 32047.54 | AE18: =SUM(AD$18,'Statistics NZ'!AE$18-'Statistics NZ'!AD$18,$B$12/5*(AE$8-AE$9)*1000) -> 32077.54 | AF18: =SUM(AE$18,'Statistics NZ'!AF$18-'Statistics NZ'!AE$18,$B$12/5*(AF$8-AF$9)*1000) -> 32127.54 | AG18: =SUM(AF$18,'Statistics NZ'!AG$18-'Statistics NZ'!AF$18,$B$12/5*(AG$8-AG$9)*1000) -> 32217.54 | ... BI18: =SUM(BH$18,'Statistics NZ'!BI$18-'Statistics NZ'!BH$18,$B$12/5*(BI$8-BI$9)*1000) -> 34037.54
A19: 4 | B19: ='Statistics NZ'!B$19*('Economic Forecasts'!D$10-'Economic Forecasts'!D$9)*1000000/SUM('Statistics NZ'!B$15:B$29,'Statistics NZ'!B$115:B$129) -> 29049.904 | C19: ='Statistics NZ'!C$19*('Economic Forecasts'!E$10-'Economic Forecasts'!E$9)*1000000/SUM('Statistics NZ'!C$15:C$29,'Statistics NZ'!C$115:C$129) -> 28941.91 | D19: ='Statistics NZ'!D$19*('Economic Forecasts'!F$10-'Economic Forecasts'!F$9)*1000000/SUM('Statistics NZ'!D$15:D$29,'Statistics NZ'!D$115:D$129) -> 29852.411 | E19: ='Statistics NZ'!E$19*('Economic Forecasts'!G$10-'Economic Forecasts'!G$9)*1000000/SUM('Statistics NZ'!E$15:E$29,'Statistics NZ'!E$115:E$129) -> 29739.705 | F19: ='Statistics NZ'!F$19*('Economic Forecasts'!H$10-'Economic Forecasts'!H$9)*1000000/SUM('Statistics NZ'!F$15:F$29,'Statistics NZ'!F$115:F$129) -> 30681.386 | G19: ='Statistics NZ'!G$19*('Economic Forecasts'!I$10-'Economic Forecasts'!I$9)*1000000/SUM('Statistics NZ'!G$15:G$29,'Statistics NZ'!G$115:G$129) -> 32026.715 | H19: ='Statistics NZ'!H$19*('Economic Forecasts'!J$10-'Economic Forecasts'!J$9)*1000000/SUM('Statistics NZ'!H$15:H$29,'Statistics NZ'!H$115:H$129) -> 33011.871 | I19: ='Statistics NZ'!I$19*('Economic Forecasts'!K$10-'Economic Forecasts'!K$9)*1000000/SUM('Statistics NZ'!I$15:I$29,'Statistics NZ'!I$115:I$129) -> 32473.179 | ... T19: ='Statistics NZ'!T$19*('Economic Forecasts'!V$10-'Economic Forecasts'!V$9)*1000000/SUM('Statistics NZ'!T$15:T$29,'Statistics NZ'!T$115:T$129) -> 32326.871 | U19: =SUM('Statistics NZ'!U$19,$B$12/5*(U$8-U$9)*1000)*('Economic Forecasts'!W$10-'Economic Forecasts'!W$9)*1000000/SUM('Statistics NZ'!U$15:U$29,'Statistics NZ'!U$115:U$129,SUM($B$12:$D$13)*(U$8-U$9)*1000) -> 32508.177 | V19: =SUM('Statistics NZ'!V$19,$B$12/5*(V$8-V$9)*1000)*('Economic Forecasts'!X$10-'Economic Forecasts'!X$9)*1000000/SUM('Statistics NZ'!V$15:V$29,'Statistics NZ'!V$115:V$129,SUM($B$12:$D$13)*(V$8-V$9)*1000) -> 33170.919 | W19: =SUM('Statistics NZ'!W$19,$B$12/5*(W$8-W$9)*1000)*('Economic Forecasts'!Y$10-'Economic Forecasts'!Y$9)*1000000/SUM('Statistics NZ'!W$15:W$29,'Statistics NZ'!W$115:W$129,SUM($B$12:$D$13)*(W$8-W$9)*1000) -> 30739.387 | X19: =SUM('Statistics NZ'!X$19,$B$12/5*(X$8-X$9)*1000)*('Economic Forecasts'!Z$10-'Economic Forecasts'!Z$9)*1000000/SUM('Statistics NZ'!X$15:X$29,'Statistics NZ'!X$115:X$129,SUM($B$12:$D$13)*(X$8-X$9)*1000) -> 31276.386 | Y19: =SUM('Statistics NZ'!Y$19,$B$12/5*(Y$8-Y$9)*1000)*('Economic Forecasts'!AA$10-'Economic Forecasts'!AA$9)*1000000/SUM('Statistics NZ'!Y$15:Y$29,'Statistics NZ'!Y$115:Y$129,SUM($B$12:$D$13)*(Y$8-Y$9)*1000) -> 32216.104 | Z19: =SUM(Y$19,'Statistics NZ'!Z$19-'Statistics NZ'!Y$19,$B$12/5*(Z$8-Z$9)*1000) -> 32279.317 | AA19: =SUM(Z$19,'Statistics NZ'!AA$19-'Statistics NZ'!Z$19,$B$12/5*(AA$8-AA$9)*1000) -> 32317.245 | AB19: =SUM(AA$19,'Statistics NZ'!AB$19-'Statistics NZ'!AA$19,$B$12/5*(AB$8-AB$9)*1000) -> 32330.944 | AC19: =SUM(AB$19,'Statistics NZ'!AC$19-'Statistics NZ'!AB$19,$B$12/5*(AC$8-AC$9)*1000) -> 32320.944 | AD19: =SUM(AC$19,'Statistics NZ'!AD$19-'Statistics NZ'!AC$19,$B$12/5*(AD$8-AD$9)*1000) -> 32320.944 | AE19: =SUM(AD$19,'Statistics NZ'!AE$19-'Statistics NZ'!AD$19,$B$12/5*(AE$8-AE$9)*1000) -> 32330.944 | AF19: =SUM(AE$19,'Statistics NZ'!AF$19-'Statistics NZ'!AE$19,$B$12/5*(AF$8-AF$9)*1000) -> 32360.944 | AG19: =SUM(AF$19,'Statistics NZ'!AG$19-'Statistics NZ'!AF$19,$B$12/5*(AG$8-AG$9)*1000) -> 32420.944 | ... BI19: =SUM(BH$19,'Statistics NZ'!BI$19-'Statistics NZ'!BH$19,$B$12/5*(BI$8-BI$9)*1000) -> 34310.944
